Workbook
Name TablaTasas: 'Tasas de Cambio'!$B$11:$E$15
Name NumPersonas: 'Tasas de Cambio'!$C$5

Sheet Resumen Comparativo
A1: COMPARATIVO DE PLANES — EUROPA 2027
A2: 3 personas
A4: Itinerario | B4: Crucero (11 días) | C4: Crucero y Zurich (16 días) | D4: Cotización (31 días, plan completo) | E4: Opción 4: Múnich (16 días, 100% cotizado)
A5: Ruta | B5: Barcelona → Crucero Mediterráneo → Venecia | C5: Zúrich → Barcelona → Crucero → Venecia | D5: Zúrich → París → Barcelona → Crucero → Venecia → Roma → Praga → Berlín → Múnich | E5: Múnich → Barcelona → Crucero → Venecia
A6: Fechas | B6: 5 – 16 mayo 2027 | C6: 1 – 16 mayo 2027 | D6: 29 abril – 30 mayo 2027 | E6: 1 – 16 mayo 2027
A7: Desglose por categoría (COP)
A8: Vuelos y Trenes | B8: 8840310 | C8: 12637329 | D8: 16266882 | E8: 10380005
A9: Traslados | B9: 1241448.6 | C9: 1606218.6 | D9: 2467285.8 | E9: 1804038.6
A10: Alojamiento | B10: 3450552 | C10: 7098252 | D10: 12743220 | E10: 5888442
A11: Crucero | B11: 6468682.5 | C11: 6468682.5 | D11: 6468682.5 | E11: 6468682.5
A12: Tours y Excursiones | B12: 2171956.5 | C12: 9876447 | D12: 12080007 | E12: 6322613.8
A13: Comidas | B13: 1800288 | C13: 4475268 | D13: 8377740 | E13: 3600576
A14: Seguro de Viaje | B14: 450000 | C14: 450000 | D14: 760054 | E14: 450000
A15: Otros y Extras | B15: 2400384 | C15: 2400384 | D15: 2400384 | E15: 2400384
A16: TOTAL GENERAL (COP) | B16: 26823622 | C16: 45012581 | D16: 61564256 | E16: 37314742
A17: TOTAL GENERAL (USD) | B17: 8334.85 | C17: 13986.66 | D17: 19129.731 | E17: 11594.73
A19: Por persona (COP)
A20: Costo por persona (COP) | B20: 8941207.2 | C20: 15004194 | D20: 20521419 | E20: 12438247
A21: Costo por persona (USD) | B21: 2778.28 | C21: 4662.22 | D21: 6376.5769 | E21: 3864.91
A22: Costo por persona/día (COP) | B22: 812837.02 | C22: 937762.11 | D22: 661981.24 | E22: 777390.46
E23: 740083.04
A25: Los 4 planes ya están completamente cotizados (sin pendientes). "Crucero" no incluye Zúrich; "Crucero y Zurich" agrega la estadía en Suiza; "Opción 4" reemplaza Zúrich por Múnich (misma duración); "Cotización" es el plan completo de un mes por 9 ciudades.

Sheet Instrucciones
B2: EUROPA 2027 — COTIZACIÓN DE VIAJE
B3: Itinerario completo · Del 30 de abril al 29 de mayo de 2027 (30 días / 29 noches) · 3 personas
B5: CÓMO USAR ESTA PLANTILLA
B6: 1. Tasas de Cambio | C6: Actualiza las tasas de cada moneda a COP (celdas amarillas). Trae valores de referencia de hoy; verifícalos antes de cotizar en firme.
B7: 2. Config. rápida | C7: En la misma hoja, ajusta el número de personas si cambia (por defecto 3) — todo el archivo se recalcula solo.
B8: 3. Cotización | C8: Registra cada costo en su MONEDA ORIGINAL (la que te cobra el proveedor: CHF, EUR, CZK, USD o COP). No conviertas manualmente: la hoja lo hace por ti.
B9: 4. Celdas amarillas | C9: Son las únicas que debes llenar: costo unitario, cantidad y moneda. Las demás columnas (totales, conversión) son fórmulas — no las edites.
B10: 5. Filas ya cargadas | C10: Contienen la estructura del itinerario (ciudad, fechas, concepto) para que solo agregues precios. Puedes insertar filas nuevas dentro de cada bloque si necesitas más líneas — copia el formato de una fila existente.
B11: 6. Resumen | C11: Muestra el total por categoría, el total general y el costo por persona, en COP y en USD, actualizados automáticamente.
B13: LEYENDA DE COLORES
C14: Celda para llenar (dato editable: costo, cantidad, moneda, tasa de cambio)
C15: Fórmula / cálculo automático — no editar
C16: Encabezados y títulos de sección
B18: ESTRUCTURA DEL ARCHIVO
B19: Tasas de Cambio | C19: Tipos de cambio y número de personas (parámetros del archivo).
B20: Cotización | C20: Detalle línea por línea de todo el itinerario: vuelos, trenes, alojamiento, crucero, tours, comidas, seguro y extras.
B21: Resumen | C21: Tablero con totales por categoría, total general y costo por persona (COP y USD).
B24: Nota: las tasas de cambio precargadas son referenciales (agosto 2026, fuente Xe.com). Los precios de vuelos, hoteles, crucero y tours NO están incluidos — debes cotizarlos con tus proveedores y digitarlos en la hoja 'Cotización'.

Sheet Tasas de Cambio
B2: TASAS DE CAMBIO Y CONFIGURACIÓN
B4: CONFIGURACIÓN DEL VIAJE
B5: Número de personas | C5: 3 | D5: ← editable, usado en toda la hoja Resumen
B6: Moneda base del reporte | C6: COP | D6: Todos los totales se consolidan en Pesos Colombianos
B7: Fecha de actualización de tasas | C7: 30/08/2026 | E7: 1.05
B9: TIPOS DE CAMBIO A PESO COLOMBIANO (COP)
B10: Código | C10: Moneda / País(es) donde se usa | D10: Símbolo | E10: Tasa (1 unidad = X COP) | F10: Fuente / Notas
B11: EUR | C11: Euro — Francia, España, Italia, Croacia, Alemania | D11: € | E11: =3608*$E$7 -> 3788.4 | F11: Xe.com, referencial 24-ago-2026
B12: CHF | C12: Franco suizo — Suiza | D12: CHF | E12: =3846*$E$7 -> 4038.3 | F12: Xe.com, referencial 24-ago-2026
B13: CZK | C13: Corona checa — República Checa | D13: Kč | E13: =149.5*$E$7 -> 156.97 | F13: Xe.com, referencial 24-ago-2026
B14: USD | C14: Dólar estadounidense — vuelos internacionales / referencia | D14: US$ | E14: =3108*$E$7 -> 3263.4 | F14: Xe.com, referencial 24-ago-2026
B15: COP | C15: Peso colombiano — Colombia (moneda base) | D15: $ | E15: 1 | F15: Moneda base — no requiere conversión
B17: ⚠ Actualiza estas 5 celdas amarillas con la tasa del día antes de enviar la cotización final al cliente. Toda la hoja 'Cotización' y 'Resumen' se recalcula automáticamente.

Sheet Cotización
A2: COTIZACIÓN DETALLADA — EUROPA 2027 (30 Abr – 29 May 2027) | O2: Vuelos y Trenes | P2: EUR
O3: Traslados | P3: CHF
A4: Categoría | B4: Ciudad / País | C4: Fechas | D4: Concepto / Descripción | E4: Moneda | F4: Costo Unitario (moneda original) | G4: Cantidad | H4: Costo Total (moneda original) | I4: Tasa de Cambio a COP | J4: Costo Total (COP) | K4: Costo por Persona (COP) | L4: Notas | M4: Fecha confirmación precio | O4: Alojamiento | P4: CZK
A5: Seguro de Viaje | B5: Internacional | C5: 7 – 31 May 2027 (25 días de cobertura) | D5: Asistencia médica internacional | E5: COP | F5: 443970 | G5: 3 | H5: =IFERROR(F5*G5,0) -> 1331910 | I5: {=IFERROR(INDEX('Tasas de Cambio'!$E$11:$E$15,MATCH(E5,'Tasas de Cambio'!$B$11:$B$15,0)),0)} -> 1 | J5: =IFERROR(H5*I5,0) -> 1331910 | K5: =IFERROR(J5/'Tasas de Cambio'!$C$5,0) -> 443970 | L5: Asistencia médica internacional, cobertura USD 60.000 (Cuponatic). https://www.cuponatic.com.co/descuento/asistencia-medica-internacional-cobertura-de-usd-60-000?m=tarjetas-de-asistencia&id_descuento=212587 | M5: 27 ago 2026
A6: Vuelos y Trenes | B6: Bogota / Barcelona | C6: 7 May 2027 | D6: Vuelo internacional Bogotá → Barcelona (ida y vuelta) | E6: COP | F6: 2740300 | G6: 3 | H6: =IFERROR(F6*G6,0) -> 8220900 | I6: {=IFERROR(INDEX('Tasas de Cambio'!$E$11:$E$15,MATCH(E6,'Tasas de Cambio'!$B$11:$B$15,0)),0)} -> 1 | J6: =IFERROR(H6*I6,0) -> 8220900 | K6: =IFERROR(J6/'Tasas de Cambio'!$C$5,0) -> 2740300 | L6: Iberia IB0156, BOG 12:35 (hora Colombia) → MAD 05:15 (+1, local); conexión → BCN 08:25 local. Incluye regreso. | M6: 11 sep 2026
A7: Traslados | B7: Alemania | C7: 31 May 2027 | D7: Traslado hotel → aeropuerto, Berlín | E7: EUR | F7: 65 | G7: 1 | H7: =IFERROR(F7*G7,0) -> 65 | I7: {=IFERROR(INDEX('Tasas de Cambio'!$E$11:$E$15,MATCH(E7,'Tasas de Cambio'!$B$11:$B$15,0)),0)} -> 3788.4 | J7: =IFERROR(H7*I7,0) -> 246246 | K7: =IFERROR(J7/'Tasas de Cambio'!$C$5,0) -> 82082 | L7: Estimado: Uber/taxi al aeropuerto BER desde Alexanderplatz/Mitte, ~35-45 min, €60-75. | M7: 11 sep 2026
A9: Otros y Extras | B9: — | C9: Contingencia | D9: Imprevistos / gastos varios (contingencia) | E9: EUR | F9: 200 | G9: 3 | H9: 600 | I9: {=IFERROR(INDEX('Tasas de Cambio'!$E$11:$E$15,MATCH(E9,'Tasas de Cambio'!$B$11:$B$15,0)),0)} -> 3788.4 | J9: 2273040 | K9: =IFERROR(J9/'Tasas de Cambio'!$C$5,0) -> 757680 | L9: Aplica solo al plan corto — revisar si alcanza para 30 días | O9: Otros y Extras
A10: Otros y Extras | B10: — | C10: Durante el viaje | D10: SIM card de viaje (datos internacionales) | E10: USD | F10: 54 | G10: 1 | H10: 54 | I10: {=IFERROR(INDEX('Tasas de Cambio'!$E$11:$E$15,MATCH(E10,'Tasas de Cambio'!$B$11:$B$15,0)),0)} -> 3263.4 | J10: 176223.6 | K10: =IFERROR(J10/'Tasas de Cambio'!$C$5,0) -> 58741.2 | L10: SIM compartida entre las 3 personas para 17 días del viaje. https://esim.holafly.com/es/esim-europa/?selectedDays=17&startDate=2027-04-30&endDate=2027-05-16 | M10: 27 ago 2026
A15: Vuelos y Trenes | B15: Francia / Rep. Checa | C15: 23 May 2027 | D15: Vuelo interno París → Praga | E15: EUR | F15: 85 | G15: 3 | H15: =IFERROR(F15*G15,0) -> 255 | I15: {=IFERROR(INDEX('Tasas de Cambio'!$E$11:$E$15,MATCH(E15,'Tasas de Cambio'!$B$11:$B$15,0)),0)} -> 3788.4 | J15: =IFERROR(H15*I15,0) -> 966042 | K15: =IFERROR(J15/'Tasas de Cambio'!$C$5,0) -> 322014 | L15: Vuelo low-cost, París → Praga, directo, ~1h50m. Maleta de mano incluida; facturada aparte. https://www.skyscanner.com/routes/pari/prg/paris-to-prague.html | M15: 11 sep 2026
A17: Traslados | B17: Francia | C17: 20 May 2027 | D17: Traslado aeropuerto → hotel, París | E17: EUR | F17: 50 | G17: 1 | H17: =IFERROR(F17*G17,0) -> 50 | I17: {=IFERROR(INDEX('Tasas de Cambio'!$E$11:$E$15,MATCH(E17,'Tasas de Cambio'!$B$11:$B$15,0)),0)} -> 3788.4 | J17: =IFERROR(H17*I17,0) -> 189420 | K17: =IFERROR(J17/'Tasas de Cambio'!$C$5,0) -> 63140 | L17: Estimado: Uber/taxi desde el aeropuerto (CDG/Orly) al hotel, ~45-60 min, €45-60. | M17: 11 sep 2026
A18: Alojamiento | B18: París, Francia | C18: 20 – 23 May (3 noches) | D18: Hotel París — costo por noche | E18: EUR | F18: 150 | G18: 3 | H18: 450 | I18: {=IFERROR(INDEX('Tasas de Cambio'!$E$11:$E$15,MATCH(E18,'Tasas de Cambio'!$B$11:$B$15,0)),0)} -> 3788.4 | J18: 1704780 | K18: =IFERROR(J18/'Tasas de Cambio'!$C$5,0) -> 568260 | L18: Recomendado: Hôtel Augustin - Astotel, boutique 4*, a 1 min de Boulevard Haussmann y 500m de Gare Saint-Lazare (zona Opéra/Grands Boulevards, muy céntrica y bien conectada). Cadena Astotel, buena calificación en Booking (~8.5+). https://www.booking.com/budget/city/fr/paris.en-gb.html
A19: Comidas | B19: París | C19: 20 May 2027 | D19: Comida del día (desayuno, almuerzo y cena) | E19: EUR | F19: 62 | G19: 3 | H19: =IFERROR(F19*G19,0) -> 186 | I19: {=IFERROR(INDEX('Tasas de Cambio'!$E$11:$E$15,MATCH(E19,'Tasas de Cambio'!$B$11:$B$15,0)),0)} -> 3788.4 | J19: =IFERROR(H19*I19,0) -> 704642.4 | K19: =IFERROR(J19/'Tasas de Cambio'!$C$5,0) -> 234880.8 | M19: 28 ago 2026
A20: Tours y Excursiones | B20: Francia | C20: 21 May 2027 | D20: Entrada Disneyland Paris — 1 día / 2 parques | E20: EUR | F20: 110 | G20: 3 | H20: 330 | I20: {=IFERROR(INDEX('Tasas de Cambio'!$E$11:$E$15,MATCH(E20,'Tasas de Cambio'!$B$11:$B$15,0)),0)} -> 3788.4 | J20: 1250172 | K20: =IFERROR(J20/'Tasas de Cambio'!$C$5,0) -> 416724 | L20: Recomendado: Ticket 1 día / 2 parques, tarifa media temporada. https://www.attractiontickets.com/en/paris-attraction-tickets/disneyland-paris-tickets/1-day-2-parks-disneyland-paris-hopper-ticket
A21: Comidas | B21: París | C21: 21 May 2027 | D21: Comida del día (desayuno, almuerzo y cena) | E21: EUR | F21: 62 | G21: 3 | H21: =IFERROR(F21*G21,0) -> 186 | I21: {=IFERROR(INDEX('Tasas de Cambio'!$E$11:$E$15,MATCH(E21,'Tasas de Cambio'!$B$11:$B$15,0)),0)} -> 3788.4 | J21: =IFERROR(H21*I21,0) -> 704642.4 | K21: =IFERROR(J21/'Tasas de Cambio'!$C$5,0) -> 234880.8 | M21: 28 ago 2026
A22: Tours y Excursiones | B22: Francia | C22: 22 May 2027 | D22: Crucero por el Sena | E22: EUR | F22: 19 | G22: 3 | H22: 57 | I22: {=IFERROR(INDEX('Tasas de Cambio'!$E$11:$E$15,MATCH(E22,'Tasas de Cambio'!$B$11:$B$15,0)),0)} -> 3788.4 | J22: 215938.8 | K22: =IFERROR(J22/'Tasas de Cambio'!$C$5,0) -> 71979.6 | L22: Recomendado: Crucero panorámico Bateaux Mouches, 1h10m. https://ryo.co/en/articles/france/paris/how-to-take-seine-cruise-paris/
A23: Comidas | B23: París | C23: 22 May 2027 | D23: Comida del día (desayuno, almuerzo y cena) | E23: EUR | F23: 62 | G23: 3 | H23: =IFERROR(F23*G23,0) -> 186 | I23: {=IFERROR(INDEX('Tasas de Cambio'!$E$11:$E$15,MATCH(E23,'Tasas de Cambio'!$B$11:$B$15,0)),0)} -> 3788.4 | J23: =IFERROR(H23*I23,0) -> 704642.4 | K23: =IFERROR(J23/'Tasas de Cambio'!$C$5,0) -> 234880.8 | M23: 28 ago 2026
A25: Traslados | B25: Francia | C25: 23 May 2027 | D25: Traslado hotel → aeropuerto, París | E25: EUR | F25: 50 | G25: 1 | H25: 50 | I25: {=IFERROR(INDEX('Tasas de Cambio'!$E$11:$E$15,MATCH(E25,'Tasas de Cambio'!$B$11:$B$15,0)),0)} -> 3788.4 | J25: 189420 | K25: =IFERROR(J25/'Tasas de Cambio'!$C$5,0) -> 63140 | L25: Estimado: Uber/taxi al aeropuerto (CDG/Orly), ~45-60 min, €45-60.
A26: Traslados | B26: España | C26: 7 May 2027 | D26: Traslado aeropuerto → hotel, Barcelona | E26: EUR | F26: 40 | G26: 1 | H26: 40 | I26: {=IFERROR(INDEX('Tasas de Cambio'!$E$11:$E$15,MATCH(E26,'Tasas de Cambio'!$B$11:$B$15,0)),0)} -> 3788.4 | J26: 151536 | K26: =IFERROR(J26/'Tasas de Cambio'!$C$5,0) -> 50512
A27: Alojamiento | B27: Barcelona, España | C27: 7 – 9 May (2 noches, pre-crucero) | D27: Hotel Barcelona — costo total (2 noches) | E27: COP | F27: 1900000 | G27: 1 | H27: =IFERROR(F27*G27,0) -> 1900000 | I27: {=IFERROR(INDEX('Tasas de Cambio'!$E$11:$E$15,MATCH(E27,'Tasas de Cambio'!$B$11:$B$15,0)),0)} -> 1 | J27: =IFERROR(H27*I27,0) -> 1900000 | K27: =IFERROR(J27/'Tasas de Cambio'!$C$5,0) -> 633333.33 | L27: Sagrada Familia, 2 noches (7-9 may). https://www.booking.com/hotel/es/sagradafamilia.es.html?aid=2311236&label=es-co-booking-desktop-vjGZbEFOhRc3a9njxeT3IwS652829002024%3Apl%3Ata%3Ap1%3Ap2%3Aac%3Aap%3Aneg%3Afi%3Atikwd-65526620%3Alp9246960%3Ali%3Adec%3Adm&sid=f6a1a9bb810c453f7b5f1225205f1f26&all_sr_blocks=9118812_91908190_0_2_0&checkin=2027-05-07&checkout=2027-05-09&dest_id=-372490&dest_type=city&dist=0&group_adults=3&group_children=0&hapos=1&highlighted_blocks=9118812_91908190_0_2_0&hpos=1&matching_block_id=9118812_91908190_0_2_0&no_rooms=1&req_adults=3&req_children=0&room1=A%2CA%2CA&sb_price_type=total&sr_order=popularity&sr_pri_blocks=9118812_91908190_0_2_0__37600&srepoch=1787875557&srpvid=a2d600b07c230149&type=total&ucfs=1 | M27: 27 ago 2026
A28: Comidas | B28: Barcelona | C28: 7 May 2027 | D28: cena | E28: EUR | F28: 15 | G28: 3 | H28: 45 | I28: {=IFERROR(INDEX('Tasas de Cambio'!$E$11:$E$15,MATCH(E28,'Tasas de Cambio'!$B$11:$B$15,0)),0)} -> 3788.4 | J28: 170478 | K28: =IFERROR(J28/'Tasas de Cambio'!$C$5,0) -> 56826
A29: Traslados | B29: Barcelona | C29: 8 May 2027 | D29: Bus, 4 trayectos | E29: EUR | F29: 12 | G29: 3 | H29: 36 | I29: {=IFERROR(INDEX('Tasas de Cambio'!$E$11:$E$15,MATCH(E29,'Tasas de Cambio'!$B$11:$B$15,0)),0)} -> 3788.4 | J29: 136382.4 | K29: =IFERROR(J29/'Tasas de Cambio'!$C$5,0) -> 45460.8
A30: Tours y Excursiones | B30: Barcelona | C30: 8 May 2027 | D30: Tour Barcelona Modernista | E30: USD | F30: 10 | G30: 3 | H30: =IFERROR(F30*G30,0) -> 30 | I30: {=IFERROR(INDEX('Tasas de Cambio'!$E$11:$E$15,MATCH(E30,'Tasas de Cambio'!$B$11:$B$15,0)),0)} -> 3263.4 | J30: =IFERROR(H30*I30,0) -> 97902 | K30: =IFERROR(J30/'Tasas de Cambio'!$C$5,0) -> 32634 | L30: Tour guiado por el Modernismo catalán en Barcelona. https://www.civitatis.com/es/barcelona/tour-barcelona-modernista/ | M30: 27 ago 2026
A31: Comidas | B31: Barcelona | C31: 8 May 2027 | D31: 3 comidas | E31: EUR | F31: 30 | G31: 3 | H31: 90 | I31: {=IFERROR(INDEX('Tasas de Cambio'!$E$11:$E$15,MATCH(E31,'Tasas de Cambio'!$B$11:$B$15,0)),0)} -> 3788.4 | J31: 340956 | K31: =IFERROR(J31/'Tasas de Cambio'!$C$5,0) -> 113652
A32: Traslados | B32: España | C32: 9 May 2027 | D32: Traslado hotel → puerto (embarque crucero), Barcelona | E32: EUR | F32: 30 | G32: 1 | H32: 30 | I32: {=IFERROR(INDEX('Tasas de Cambio'!$E$11:$E$15,MATCH(E32,'Tasas de Cambio'!$B$11:$B$15,0)),0)} -> 3788.4 | J32: 113652 | K32: =IFERROR(J32/'Tasas de Cambio'!$C$5,0) -> 37884
A33: Crucero | B33: Mediterráneo | C33: 9 – 16 May (7 noches) | D33: Crucero Barcelona → Ravena — tarifa por persona (cabina) | E33: USD | F33: 670 | G33: 3 | H33: =IFERROR(F33*G33,0) -> 2010 | I33: {=IFERROR(INDEX('Tasas de Cambio'!$E$11:$E$15,MATCH(E33,'Tasas de Cambio'!$B$11:$B$15,0)),0)} -> 3263.4 | J33: =IFERROR(H33*I33,0) -> 6559434 | K33: =IFERROR(J33/'Tasas de Cambio'!$C$5,0) -> 2186478 | L33: Crucero Barcelona-Ravena, 7 noches, incluye propinas. https://www.royalcaribbean.com/lac/es/itinerary/7-night-italy-croatia-cruise-from-barcelona-on-brilliance-BR07M885?sailDate=2027-05-08&packageCode=BR07M885&groupId=BR07BCN-1768961711&country=COL&search=startDate:2027-05-01~2027-05-31 | M33: 27 ago 2026
A34: Tours y Excursiones | B34: Barcelona | C34: 9 May 2027 | D34: N/A (día de embarque) | E34: EUR | F34: 0 | G34: 3 | H34: 0 | I34: {=IFERROR(INDEX('Tasas de Cambio'!$E$11:$E$15,MATCH(E34,'Tasas de Cambio'!$B$11:$B$15,0)),0)} -> 3788.4 | J34: 0 | K34: =IFERROR(J34/'Tasas de Cambio'!$C$5,0) -> 0
A35: Comidas | B35: Barcelona | C35: 9 May 2027 | D35: desayuno | E35: EUR | F35: 10 | G35: 3 | H35: 30 | I35: {=IFERROR(INDEX('Tasas de Cambio'!$E$11:$E$15,MATCH(E35,'Tasas de Cambio'!$B$11:$B$15,0)),0)} -> 3788.4 | J35: 113652 | K35: =IFERROR(J35/'Tasas de Cambio'!$C$5,0) -> 37884
A36: Traslados | B36: Venecia | C36: 16 May 2027 | D36: Vaporetti ACTV | E36: EUR | F36: 25 | G36: 3 | H36: =IFERROR(F36*G36,0) -> 75 | I36: {=IFERROR(INDEX('Tasas de Cambio'!$E$11:$E$15,MATCH(E36,'Tasas de Cambio'!$B$11:$B$15,0)),0)} -> 3788.4 | J36: =IFERROR(H36*I36,0) -> 284130 | K36: =IFERROR(J36/'Tasas de Cambio'!$C$5,0) -> 94710 | L36: Boletos de vaporetto (transporte acuático) por Venecia. https://book.tickets-venice.com/es/book/8748/select/?_gl=1%2A1073ils%2A_gcl_aw%2AR0NMLjE3ODc4NzgwODMuRUFJYUlRb2JDaE1JaFpPNjdZekNsZ01Wd1lSYUJSM2Y1U1JPRUFBWUF5QUFFZ0tjeFBEX0J3RQ..%2A_gcl_au%2ANzIxMTA1MTQ5LjE3ODc4NzgwODMuLS4tLjE3ODc4NzgwODMuMTE2MDU2ODc1MS4xNzg3ODc4MDg0LjE3ODc4NzgwODM.%2A_ga%2ANDcyOTU3MzYyLjE3ODc4NzgwODM.%2A_ga_Y45PC9R73C%2AczE3ODc4NzgwODMkbzEkZzAkdDE3ODc4NzgwODQkajU5JGwwJGgw&cookieBanner=false&date=2027-05-15&tourId=15560&variantId=15560 | M36: 27 ago 2026
A37: Tours y Excursiones | B37: La Spezia (Florencia/Pisa) | C37: 11 May 2027 | D37: Panoramic Pisa | E37: USD | F37: 70 | G37: 3 | H37: =IFERROR(F37*G37,0) -> 210 | I37: {=IFERROR(INDEX('Tasas de Cambio'!$E$11:$E$15,MATCH(E37,'Tasas de Cambio'!$B$11:$B$15,0)),0)} -> 3263.4 | J37: =IFERROR(H37*I37,0) -> 685314 | K37: =IFERROR(J37/'Tasas de Cambio'!$C$5,0) -> 228438 | L37: Excursión panorámica por Pisa desde el crucero. https://www.royalcaribbean.com/account/cruise-planner/category/shorex/product/Y8RO?bookingId=3113096&shipCode=BR&sailDate=20270508 | M37: 27 ago 2026
A38: Comidas | B38: La Spezia (Florencia/Pisa) | C38: 11 May 2027 | D38: Almuerzo en tierra | E38: EUR | F38: 25 | G38: 3 | H38: =IFERROR(F38*G38,0) -> 75 | I38: {=IFERROR(INDEX('Tasas de Cambio'!$E$11:$E$15,MATCH(E38,'Tasas de Cambio'!$B$11:$B$15,0)),0)} -> 3788.4 | J38: =IFERROR(H38*I38,0) -> 284130 | K38: =IFERROR(J38/'Tasas de Cambio'!$C$5,0) -> 94710 | L38: Desayuno y cena incluidos en el crucero, almuerzo en Pisa/Florencia | M38: 28 ago 2026
A39: Tours y Excursiones | B39: Civitavecchia (Roma) | C39: 12 May 2027 | D39: Visit to Rome | E39: USD | F39: 142 | G39: 3 | H39: =IFERROR(F39*G39,0) -> 426 | I39: {=IFERROR(INDEX('Tasas de Cambio'!$E$11:$E$15,MATCH(E39,'Tasas de Cambio'!$B$11:$B$15,0)),0)} -> 3263.4 | J39: =IFERROR(H39*I39,0) -> 1390208.4 | K39: =IFERROR(J39/'Tasas de Cambio'!$C$5,0) -> 463402.8 | L39: Excursión a Roma desde el crucero. https://www.royalcaribbean.com/account/cruise-planner/category/shorex/product/CV1F?bookingId=3113096&shipCode=BR&sailDate=20270508 | M39: 29 ago 2026
A40: Comidas | B40: Civitavecchia (Roma) | C40: 12 May 2027 | D40: Almuerzo en tierra | E40: EUR | F40: 25 | G40: 3 | H40: =IFERROR(F40*G40,0) -> 75 | I40: {=IFERROR(INDEX('Tasas de Cambio'!$E$11:$E$15,MATCH(E40,'Tasas de Cambio'!$B$11:$B$15,0)),0)} -> 3788.4 | J40: =IFERROR(H40*I40,0) -> 284130 | K40: =IFERROR(J40/'Tasas de Cambio'!$C$5,0) -> 94710 | L40: Desayuno y cena incluidos en el crucero, almuerzo en Roma | M40: 28 ago 2026
A41: Tours y Excursiones | B41: Salerno (Costa Amalfitana) | C41: 13 May 2027 | D41: Tour a pie gratis | E41: EUR | F41: 0 | G41: 3 | H41: 0 | I41: {=IFERROR(INDEX('Tasas de Cambio'!$E$11:$E$15,MATCH(E41,'Tasas de Cambio'!$B$11:$B$15,0)),0)} -> 3788.4 | J41: 0 | K41: =IFERROR(J41/'Tasas de Cambio'!$C$5,0) -> 0
A42: Comidas | B42: Salerno (Costa Amalfitana) | C42: 13 May 2027 | D42: Incluida en el crucero (come a bordo) | E42: EUR | F42: 0 | G42: 3 | H42: =IFERROR(F42*G42,0) -> 0 | I42: {=IFERROR(INDEX('Tasas de Cambio'!$E$11:$E$15,MATCH(E42,'Tasas de Cambio'!$B$11:$B$15,0)),0)} -> 3788.4 | J42: =IFERROR(H42*I42,0) -> 0 | K42: =IFERROR(J42/'Tasas de Cambio'!$C$5,0) -> 0 | L42: Comida incluida en el paquete del crucero, sin costo adicional | M42: 27 ago 2026
A43: Vuelos y Trenes | B43: Italia | C43: 16 May 2027 | D43: Tren Ravenna - Venecia St Lucia | E43: EUR | F43: 25 | G43: 3 | H43: =IFERROR(F43*G43,0) -> 75 | I43: {=IFERROR(INDEX('Tasas de Cambio'!$E$11:$E$15,MATCH(E43,'Tasas de Cambio'!$B$11:$B$15,0)),0)} -> 3788.4 | J43: =IFERROR(H43*I43,0) -> 284130 | K43: =IFERROR(J43/'Tasas de Cambio'!$C$5,0) -> 94710 | L43: Tren regional desde Ravenna hasta Venecia Santa Lucia. https://www.trenitalia.com/en.html | M43: 27 ago 2026
A44: Traslados | B44: Zadar, Croacia | C44: 15 May 2027 | D44: Transporte - Tour a pie gratis | E44: EUR | F44: 10 | G44: 3 | H44: =IFERROR(F44*G44,0) -> 30 | I44: {=IFERROR(INDEX('Tasas de Cambio'!$E$11:$E$15,MATCH(E44,'Tasas de Cambio'!$B$11:$B$15,0)),0)} -> 3788.4 | J44: =IFERROR(H44*I44,0) -> 113652 | K44: =IFERROR(J44/'Tasas de Cambio'!$C$5,0) -> 37884 | M44: 27 ago 2026
A45: Comidas | B45: Zadar, Croacia | C45: 15 May 2027 | D45: Incluida en el crucero (come a bordo) | E45: EUR | F45: 0 | G45: 3 | H45: =IFERROR(F45*G45,0) -> 0 | I45: {=IFERROR(INDEX('Tasas de Cambio'!$E$11:$E$15,MATCH(E45,'Tasas de Cambio'!$B$11:$B$15,0)),0)} -> 3788.4 | J45: =IFERROR(H45*I45,0) -> 0 | K45: =IFERROR(J45/'Tasas de Cambio'!$C$5,0) -> 0 | L45: Comida incluida en el paquete del crucero, sin costo adicional | M45: 27 ago 2026
A46: Traslados | B46: Italia | C46: 16 May 2027 | D46: Traslado puerto → Estación Ravenna | E46: EUR | F46: 12 | G46: 3 | H46: =IFERROR(F46*G46,0) -> 36 | I46: {=IFERROR(INDEX('Tasas de Cambio'!$E$11:$E$15,MATCH(E46,'Tasas de Cambio'!$B$11:$B$15,0)),0)} -> 3788.4 | J46: =IFERROR(H46*I46,0) -> 136382.4 | K46: =IFERROR(J46/'Tasas de Cambio'!$C$5,0) -> 45460.8 | M46: 27 ago 2026
A47: Alojamiento | B47: Venecia, Italia | C47: 16 – 17 May (1 noche, post-crucero) | D47: Hotel Venecia — costo total (1 noche) | E47: EUR | F47: 400 | G47: 1 | H47: =IFERROR(F47*G47,0) -> 400 | I47: {=IFERROR(INDEX('Tasas de Cambio'!$E$11:$E$15,MATCH(E47,'Tasas de Cambio'!$B$11:$B$15,0)),0)} -> 3788.4 | J47: =IFERROR(H47*I47,0) -> 1515360 | K47: =IFERROR(J47/'Tasas de Cambio'!$C$5,0) -> 505120 | M47: 28 ago 2026
A48: Comidas | B48: Rávena (Venecia) | C48: 16 May 2027 | D48: Almuerzo y cena | E48: EUR | F48: 30 | G48: 3 | H48: 90 | I48: {=IFERROR(INDEX('Tasas de Cambio'!$E$11:$E$15,MATCH(E48,'Tasas de Cambio'!$B$11:$B$15,0)),0)} -> 3788.4 | J48: 340956 | K48: =IFERROR(J48/'Tasas de Cambio'!$C$5,0) -> 113652
...

Sheet Resumen
B2: RESUMEN DE COTIZACIÓN — EUROPA 2027
B3: 30 de abril al 29 de mayo de 2027 · 30 días / 29 noches
B5: TOTAL POR CATEGORÍA
B6: Categoría | C6: Total (COP) | D6: Total (USD) | E6: % del total
B7: Vuelos y Trenes | C7: =SUMIF('Cotización'!$A:$A,B7,'Cotización'!$J:$J) -> 16266882 | D7: =IFERROR(C7/'Tasas de Cambio'!$E$14,0) -> 5054.5738 | E7: =IFERROR(C7/$C$15,0) -> 0.26422608
B8: Traslados | C8: =SUMIF('Cotización'!$A:$A,B8,'Cotización'!$J:$J) -> 2467285.8 | D8: =IFERROR(C8/'Tasas de Cambio'!$E$14,0) -> 766.65449 | E8: =IFERROR(C8/$C$15,0) -> 0.040076596
B9: Alojamiento | C9: =SUMIF('Cotización'!$A:$A,B9,'Cotización'!$J:$J) -> 12743220 | D9: =IFERROR(C9/'Tasas de Cambio'!$E$14,0) -> 3959.6737 | E9: =IFERROR(C9/$C$15,0) -> 0.20699056
B10: Crucero | C10: =SUMIF('Cotización'!$A:$A,B10,'Cotización'!$J:$J) -> 6468682.5 | D10: =IFERROR(C10/'Tasas de Cambio'!$E$14,0) -> 2010 | E10: =IFERROR(C10/$C$15,0) -> 0.10507205
B11: Tours y Excursiones | C11: =SUMIF('Cotización'!$A:$A,B11,'Cotización'!$J:$J) -> 12080007 | D11: =IFERROR(C11/'Tasas de Cambio'!$E$14,0) -> 3753.5951 | E11: =IFERROR(C11/$C$15,0) -> 0.19621788
B12: Comidas | C12: =SUMIF('Cotización'!$A:$A,B12,'Cotización'!$J:$J) -> 8377740 | D12: =IFERROR(C12/'Tasas de Cambio'!$E$14,0) -> 2603.1974 | E12: =IFERROR(C12/$C$15,0) -> 0.13608124
B13: Seguro de Viaje | C13: =SUMIF('Cotización'!$A:$A,B13,'Cotización'!$J:$J) -> 760054 | D13: =IFERROR(C13/'Tasas de Cambio'!$E$14,0) -> 236.16997 | E13: =IFERROR(C13/$C$15,0) -> 0.012345703
B14: Otros y Extras | C14: =SUMIF('Cotización'!$A:$A,B14,'Cotización'!$J:$J) -> 2400384 | D14: =IFERROR(C14/'Tasas de Cambio'!$E$14,0) -> 745.86623 | E14: =IFERROR(C14/$C$15,0) -> 0.038989897
B15: TOTAL GENERAL | C15: =SUM(C7:C14) -> 61564256 | D15: =SUM(D7:D14) -> 19129.731
B17: COSTO POR PERSONA
B18: Número de personas | C18: ='Tasas de Cambio'!$C$5 -> 3
B19: Costo por persona (COP) | C19: =IFERROR($C$15/'Tasas de Cambio'!$C$5,0) -> 20521419
B20: Costo por persona (USD) | C20: =IFERROR($D$15/'Tasas de Cambio'!$C$5,0) -> 6376.5769
B21: Costo promedio por persona / día (COP) | C21: =IFERROR(C19/30,0) -> 684047.29
B23: TASAS DE CAMBIO UTILIZADAS
B24: Moneda | C24: Tasa a COP
B25: ='Tasas de Cambio'!$B$11 -> EUR | C25: ='Tasas de Cambio'!$E$11 -> 3750.6
B26: ='Tasas de Cambio'!$B$12 -> CHF | C26: ='Tasas de Cambio'!$E$12 -> 4053
B27: ='Tasas de Cambio'!$B$13 -> CZK | C27: ='Tasas de Cambio'!$E$13 -> 155.82
B28: ='Tasas de Cambio'!$B$14 -> USD | C28: ='Tasas de Cambio'!$E$14 -> 3218.25
B29: ='Tasas de Cambio'!$B$15 -> COP | C29: ='Tasas de Cambio'!$E$15 -> 1
B31: Cifras referenciales — sujetas a disponibilidad, temporada y tasa de cambio del día de pago. Documento generado como herramienta de cotización, no constituye una tarifa garantizada.

Sheet Crucero y Zurich
A2: COTIZACIÓN DETALLADA — EUROPA 2027 (01 May – 16 May 2027) | O2: Vuelos y Trenes | P2: EUR
O3: Traslados | P3: CHF
A4: Categoría | B4: Ciudad / País | C4: Fechas | D4: Concepto / Descripción | E4: Moneda | F4: Costo Unitario (moneda original) | G4: Cantidad | H4: Costo Total (moneda original) | I4: Tasa de Cambio a COP | J4: Costo Total (COP) | K4: Costo por Persona (COP) | L4: Notas | M4: Fecha confirmación precio | O4: Alojamiento | P4: CZK
A5: Tours y Excursiones | B5: Barcelona | C5: 7 May 2027 | D5: Tour Barcelona Modernista | E5: USD | F5: 10 | G5: 3 | H5: =IFERROR(F5*G5,0) -> 30 | I5: {=IFERROR(INDEX('Tasas de Cambio'!$E$11:$E$15,MATCH(E5,'Tasas de Cambio'!$B$11:$B$15,0)),0)} -> 3263.4 | J5: =IFERROR(H5*I5,0) -> 97902 | K5: =IFERROR(J5/'Tasas de Cambio'!$C$5,0) -> 32634 | L5: Tour guiado por el Modernismo catalán en Barcelona. https://www.civitatis.com/es/barcelona/tour-barcelona-modernista/ | M5: 27 ago 2026
A6: Tours y Excursiones | B6: Barcelona | C6: 7 May 2027 | D6: Free tour Sagrada Familia | E6: USD | F6: 10 | G6: 3 | H6: =IFERROR(F6*G6,0) -> 30 | I6: {=IFERROR(INDEX('Tasas de Cambio'!$E$11:$E$15,MATCH(E6,'Tasas de Cambio'!$B$11:$B$15,0)),0)} -> 3263.4 | J6: =IFERROR(H6*I6,0) -> 97902 | K6: =IFERROR(J6/'Tasas de Cambio'!$C$5,0) -> 32634 | L6: Free tour guiado por el exterior de la Sagrada Familia. https://www.civitatis.com/es/barcelona/free-tour-sagrada-familia/ | M6: 27 ago 2026
A7: Otros y Extras | B7: Navegación | C7: 9 May 2027 | D7: Día de navegación | E7: COP | F7: 0 | G7: 1 | H7: =IFERROR(F7*G7,0) -> 0 | I7: {=IFERROR(INDEX('Tasas de Cambio'!$E$11:$E$15,MATCH(E7,'Tasas de Cambio'!$B$11:$B$15,0)),0)} -> 1 | J7: =IFERROR(H7*I7,0) -> 0 | K7: =IFERROR(J7/'Tasas de Cambio'!$C$5,0) -> 0 | L7: Día de navegación, incluido en la tarifa del crucero. https://www.royalcaribbean.com/lac/es/itinerary/7-night-italy-croatia-cruise-from-barcelona-on-brilliance-BR07M885?sailDate=2027-05-08&packageCode=BR07M885&groupId=BR07BCN-1768961711&country=COL&search=startDate:2027-05-01~2027-05-31 | M7: 27 ago 2026
A8: Otros y Extras | B8: Navegación | C8: 13 May 2027 | D8: Día de navegación | E8: COP | F8: 0 | G8: 1 | H8: =IFERROR(F8*G8,0) -> 0 | I8: {=IFERROR(INDEX('Tasas de Cambio'!$E$11:$E$15,MATCH(E8,'Tasas de Cambio'!$B$11:$B$15,0)),0)} -> 1 | J8: =IFERROR(H8*I8,0) -> 0 | K8: =IFERROR(J8/'Tasas de Cambio'!$C$5,0) -> 0 | L8: Día de navegación, incluido en la tarifa del crucero. https://www.royalcaribbean.com/lac/es/itinerary/7-night-italy-croatia-cruise-from-barcelona-on-brilliance-BR07M885?sailDate=2027-05-08&packageCode=BR07M885&groupId=BR07BCN-1768961711&country=COL&search=startDate:2027-05-01~2027-05-31 | M8: 27 ago 2026
A9: Traslados | B9: Venecia | C9: 15 May 2027 | D9: Vaporetti ACTV | E9: EUR | F9: 25 | G9: 3 | H9: =IFERROR(F9*G9,0) -> 75 | I9: {=IFERROR(INDEX('Tasas de Cambio'!$E$11:$E$15,MATCH(E9,'Tasas de Cambio'!$B$11:$B$15,0)),0)} -> 3788.4 | J9: =IFERROR(H9*I9,0) -> 284130 | K9: =IFERROR(J9/'Tasas de Cambio'!$C$5,0) -> 94710 | L9: Boletos de vaporetto (transporte acuático) por Venecia. https://book.tickets-venice.com/es/book/8748/select/?_gl=1%2A1073ils%2A_gcl_aw%2AR0NMLjE3ODc4NzgwODMuRUFJYUlRb2JDaE1JaFpPNjdZekNsZ01Wd1lSYUJSM2Y1U1JPRUFBWUF5QUFFZ0tjeFBEX0J3RQ..%2A_gcl_au%2ANzIxMTA1MTQ5LjE3ODc4NzgwODMuLS4tLjE3ODc4NzgwODMuMTE2MDU2ODc1MS4xNzg3ODc4MDg0LjE3ODc4NzgwODM.%2A_ga%2ANDcyOTU3MzYyLjE3ODc4NzgwODM.%2A_ga_Y45PC9R73C%2AczE3ODc4NzgwODMkbzEkZzAkdDE3ODc4NzgwODQkajU5JGwwJGgw&cookieBanner=false&date=2027-05-15&tourId=15560&variantId=15560 | M9: 27 ago 2026
A10: Otros y Extras | C10: Durante el viaje | D10: SIM card de viaje (datos internacionales) | E10: USD | F10: 52 | G10: 1 | H10: 52 | I10: {=IFERROR(INDEX('Tasas de Cambio'!$E$11:$E$15,MATCH(E10,'Tasas de Cambio'!$B$11:$B$15,0)),0)} -> 3263.4 | J10: 169696.8 | K10: =IFERROR(J10/'Tasas de Cambio'!$C$5,0) -> 56565.6 | L10: SIM compartida entre las 3 personas para los 16 días del viaje. https://esim.holafly.com/es/esim-europa/?selectedDays=16&startDate=2027-05-01&endDate=2027-05-16 | M10: 27 ago 2026
A11: Otros y Extras | C11: Contingencia | D11: Imprevistos / gastos varios (contingencia) | E11: EUR | F11: 200 | G11: 3 | H11: 600 | I11: {=IFERROR(INDEX('Tasas de Cambio'!$E$11:$E$15,MATCH(E11,'Tasas de Cambio'!$B$11:$B$15,0)),0)} -> 3788.4 | J11: 2273040 | K11: =IFERROR(J11/'Tasas de Cambio'!$C$5,0) -> 757680
A12: Vuelos y Trenes | B12: Bogota / Zúrich | C12: 46507 | D12: Vuelo internacional Bogotá → Zúrich (ida) | E12: COP | F12: 1557040 | G12: 3 | H12: 4671120 | I12: {=IFERROR(INDEX('Tasas de Cambio'!$E$11:$E$15,MATCH(E12,'Tasas de Cambio'!$B$11:$B$15,0)),0)} -> 1 | J12: 4671120 | K12: =IFERROR(J12/'Tasas de Cambio'!$C$5,0) -> 1557040 | L12: Lufthansa, sale vie 30 abr 23:30 BOG, llega sáb 1 may 19:15 ZRH (vía FRA), 12h45m, Economy Light. Total ida+regreso $3.114.080 COP/persona, dividido entre los 2 tramos.
A13: Traslados | B13: Suiza | C13: 46508 | D13: Traslado aeropuerto → hotel, Zúrich | E13: CHF | F13: 45 | G13: 1 | H13: 45 | I13: {=IFERROR(INDEX('Tasas de Cambio'!$E$11:$E$15,MATCH(E13,'Tasas de Cambio'!$B$11:$B$15,0)),0)} -> 4038.3 | J13: 181723.5 | K13: =IFERROR(J13/'Tasas de Cambio'!$C$5,0) -> 60574.5 | L13: Estimado: Uber X / taxi Zúrich, CHF 45 aprox. (aeropuerto-centro ~20-25 min, 1 carro para el grupo). Taxi normal: CHF 50-70.
A14: Alojamiento | B14: Zúrich, Suiza | C14: 1 May – 6 May (5 noches) | D14: Hotel Zúrich — costo total (5 noches) | E14: CHF | F14: 900 | G14: 1 | H14: =IFERROR(F14*G14,0) -> 900 | I14: {=IFERROR(INDEX('Tasas de Cambio'!$E$11:$E$15,MATCH(E14,'Tasas de Cambio'!$B$11:$B$15,0)),0)} -> 4038.3 | J14: =IFERROR(H14*I14,0) -> 3634470 | K14: =IFERROR(J14/'Tasas de Cambio'!$C$5,0) -> 1211490 | M14: 27 ago 2026
A15: Seguro de Viaje | B15: Internacional | C15: 1 – 16 may 2027 (16 días de cobertura) | D15: Asistencia médica internacional | E15: COP | F15: 295980 | G15: 3 | H15: =IFERROR(F15*G15,0) -> 887940 | I15: {=IFERROR(INDEX('Tasas de Cambio'!$E$11:$E$15,MATCH(E15,'Tasas de Cambio'!$B$11:$B$15,0)),0)} -> 1 | J15: =IFERROR(H15*I15,0) -> 887940 | K15: =IFERROR(J15/'Tasas de Cambio'!$C$5,0) -> 295980 | L15: Asistencia médica internacional, cobertura USD 60.000 (Cuponatic). https://www.cuponatic.com.co/descuento/asistencia-medica-internacional-cobertura-de-usd-60-000?m=tarjetas-de-asistencia&id_descuento=212587 | M15: 27 ago 2026
A16: Tours y Excursiones | B16: Zurich | C16: 1 May 2027 | D16: City Tour, Cruise en el lago y Lindt Home of Chocolate | E16: USD | F16: 90 | G16: 3 | H16: 270 | I16: {=IFERROR(INDEX('Tasas de Cambio'!$E$11:$E$15,MATCH(E16,'Tasas de Cambio'!$B$11:$B$15,0)),0)} -> 3263.4 | J16: 881118 | K16: =IFERROR(J16/'Tasas de Cambio'!$C$5,0) -> 293706 | L16: Recomendado (4.5★, +4600 reseñas) - tour de medio día | https://www.getyourguide.com/zurich-l55/zurich-city-tour-with-cruise-chocolate-t75865/
A17: Tours y Excursiones | B17: Zurich | C17: 46509.0 | D17: Excursión Jungfraujoch (tren panorámico, por persona) | E17: USD | F17: 362 | G17: 3 | H17: =IFERROR(F17*G17,0) -> 1086 | I17: {=IFERROR(INDEX('Tasas de Cambio'!$E$11:$E$15,MATCH(E17,'Tasas de Cambio'!$B$11:$B$15,0)),0)} -> 3263.4 | J17: =IFERROR(H17*I17,0) -> 3544052.4 | K17: =IFERROR(J17/'Tasas de Cambio'!$C$5,0) -> 1181350.8 | L17: Recomendado - tour guiado de día completo desde Zúrich (12h, incl. transporte y entrada Top of Europe). https://www.civitatis.com/es/zurich/excursion-jungfraujoch/ | M17: 28 ago 2026
A18: Comidas | B18: Zurich | C18: 46509.0 | D18: Comida del día (desayuno, almuerzo y cena) | E18: CHF | F18: 70 | G18: 3 | H18: =IFERROR(F18*G18,0) -> 210 | I18: {=IFERROR(INDEX('Tasas de Cambio'!$E$11:$E$15,MATCH(E18,'Tasas de Cambio'!$B$11:$B$15,0)),0)} -> 4038.3 | J18: =IFERROR(H18*I18,0) -> 848043 | K18: =IFERROR(J18/'Tasas de Cambio'!$C$5,0) -> 282681 | L18: Estimado: ~CHF 70/persona/día (desayuno+almuerzo+cena) | M18: 28 ago 2026
A19: Tours y Excursiones | B19: Zurich | C19: 46510 | D19: Mount Pilatus & Lucerne - excursión de un día (cogwheel + góndola + crucero lago) | E19: USD | F19: 150 | G19: 3 | H19: 450 | I19: {=IFERROR(INDEX('Tasas de Cambio'!$E$11:$E$15,MATCH(E19,'Tasas de Cambio'!$B$11:$B$15,0)),0)} -> 3263.4 | J19: 1468530 | K19: =IFERROR(J19/'Tasas de Cambio'!$C$5,0) -> 489510 | L19: Recomendado (Viator, 980+ reseñas) | https://www.viator.com/tours/Zurich/Mount-Pilatus-Summer-Day-Trip-from-Zurich/d577-3885SW304BS
A20: Comidas | B20: Zurich | C20: 46510.0 | D20: Comida del día (desayuno, almuerzo y cena) | E20: CHF | F20: 70 | G20: 3 | H20: =IFERROR(F20*G20,0) -> 210 | I20: {=IFERROR(INDEX('Tasas de Cambio'!$E$11:$E$15,MATCH(E20,'Tasas de Cambio'!$B$11:$B$15,0)),0)} -> 4038.3 | J20: =IFERROR(H20*I20,0) -> 848043 | K20: =IFERROR(J20/'Tasas de Cambio'!$C$5,0) -> 282681 | L20: Estimado: ~CHF 70/persona/día (desayuno+almuerzo+cena) | M20: 28 ago 2026
A21: Tours y Excursiones | B21: Zurich | C21: 46511 | D21: Grindelwald, Interlaken y Lauterbrunnen - excursión de un día | E21: USD | F21: 138 | G21: 3 | H21: 414 | I21: {=IFERROR(INDEX('Tasas de Cambio'!$E$11:$E$15,MATCH(E21,'Tasas de Cambio'!$B$11:$B$15,0)),0)} -> 3263.4 | J21: 1351047.6 | K21: =IFERROR(J21/'Tasas de Cambio'!$C$5,0) -> 450349.2 | L21: Recomendado (4.5★, 152 reseñas) | https://www.getyourguide.com/zurich-l55/zurich-day-trip-to-grindelwald-interlaken-lauterbrunnen-t42647/
A22: Comidas | B22: Zurich | C22: 46511.0 | D22: Comida del día (desayuno, almuerzo y cena) | E22: CHF | F22: 70 | G22: 3 | H22: =IFERROR(F22*G22,0) -> 210 | I22: {=IFERROR(INDEX('Tasas de Cambio'!$E$11:$E$15,MATCH(E22,'Tasas de Cambio'!$B$11:$B$15,0)),0)} -> 4038.3 | J22: =IFERROR(H22*I22,0) -> 848043 | K22: =IFERROR(J22/'Tasas de Cambio'!$C$5,0) -> 282681 | L22: Estimado: ~CHF 70/persona/día (desayuno+almuerzo+cena) | M22: 28 ago 2026
A23: Tours y Excursiones | B23: Zurich | C23: 46512 | D23: Cataratas del Rin (Schaffhausen) - excursión de medio día | E23: USD | F23: 70 | G23: 3 | H23: 210 | I23: {=IFERROR(INDEX('Tasas de Cambio'!$E$11:$E$15,MATCH(E23,'Tasas de Cambio'!$B$11:$B$15,0)),0)} -> 3263.4 | J23: 685314 | K23: =IFERROR(J23/'Tasas de Cambio'!$C$5,0) -> 228438 | L23: Recomendado - las cataratas más grandes de Europa | https://www.viator.com/tours/Zurich/Rhine-Falls-and-Stein-am-Rhein-Half-Day-Tour-from-Zurich/d577-3885RHINESTEIN
A24: Comidas | B24: Zurich | C24: 46512.0 | D24: Comida del día (desayuno, almuerzo y cena) | E24: CHF | F24: 70 | G24: 3 | H24: =IFERROR(F24*G24,0) -> 210 | I24: {=IFERROR(INDEX('Tasas de Cambio'!$E$11:$E$15,MATCH(E24,'Tasas de Cambio'!$B$11:$B$15,0)),0)} -> 4038.3 | J24: =IFERROR(H24*I24,0) -> 848043 | K24: =IFERROR(J24/'Tasas de Cambio'!$C$5,0) -> 282681 | L24: Estimado: ~CHF 70/persona/día (desayuno+almuerzo+cena) | M24: 28 ago 2026
A25: Alojamiento | B25: Barcelona, España | C25: 6 – 8 May (2 noches, pre-crucero) | D25: Hotel Barcelona — costo total (2 noches) | E25: COP | F25: 1900000 | G25: 1 | H25: =IFERROR(F25*G25,0) -> 1900000 | I25: {=IFERROR(INDEX('Tasas de Cambio'!$E$11:$E$15,MATCH(E25,'Tasas de Cambio'!$B$11:$B$15,0)),0)} -> 1 | J25: =IFERROR(H25*I25,0) -> 1900000 | K25: =IFERROR(J25/'Tasas de Cambio'!$C$5,0) -> 633333.33 | L25: Sagrada Familia, 2 noches (6-8 may). https://www.booking.com/hotel/es/sagradafamilia.es.html?aid=2311236&label=es-co-booking-desktop-vjGZbEFOhRc3a9njxeT3IwS652829002024%3Apl%3Ata%3Ap1%3Ap2%3Aac%3Aap%3Aneg%3Afi%3Atikwd-65526620%3Alp9246960%3Ali%3Adec%3Adm&sid=f6a1a9bb810c453f7b5f1225205f1f26&all_sr_blocks=9118812_91908190_0_2_0&checkin=2027-05-06&checkout=2027-05-08&dest_id=-372490&dest_type=city&dist=0&group_adults=3&group_children=0&hapos=1&highlighted_blocks=9118812_91908190_0_2_0&hpos=1&matching_block_id=9118812_91908190_0_2_0&no_rooms=1&req_adults=3&req_children=0&room1=A%2CA%2CA&sb_price_type=total&sr_order=popularity&sr_pri_blocks=9118812_91908190_0_2_0__37600&srepoch=1787875557&srpvid=a2d600b07c230149&type=total&ucfs=1 | M25: 27 ago 2026
A26: Vuelos y Trenes | B26: Zúrich / Barcelona | C26: 46513 | D26: Vuelo Swiss Int. Air Lines Zúrich → Barcelona, directo | E26: CHF | F26: 271 | G26: 3 | H26: 813 | I26: {=IFERROR(INDEX('Tasas de Cambio'!$E$11:$E$15,MATCH(E26,'Tasas de Cambio'!$B$11:$B$15,0)),0)} -> 4038.3 | J26: 3283137.9 | K26: =IFERROR(J26/'Tasas de Cambio'!$C$5,0) -> 1094379.3 | L26: Jue 6 may, sale 07:10 ZRH, llega 08:50 BCN, directo (1h40m), Economy Light
A27: Traslados | B27: Suiza | C27: 46513 | D27: Traslado hotel → aeropuerto, Zúrich | E27: CHF | F27: 45 | G27: 1 | H27: 45 | I27: {=IFERROR(INDEX('Tasas de Cambio'!$E$11:$E$15,MATCH(E27,'Tasas de Cambio'!$B$11:$B$15,0)),0)} -> 4038.3 | J27: 181723.5 | K27: =IFERROR(J27/'Tasas de Cambio'!$C$5,0) -> 60574.5 | L27: Estimado: Uber X / taxi Zúrich, CHF 45 aprox. (aeropuerto-centro ~20-25 min, 1 carro para el grupo). Taxi normal: CHF 50-70.
A28: Traslados | B28: España | C28: 46513.0 | D28: Traslado aeropuerto → hotel, Barcelona | E28: EUR | F28: 40 | G28: 1 | H28: =IFERROR(F28*G28,0) -> 40 | I28: {=IFERROR(INDEX('Tasas de Cambio'!$E$11:$E$15,MATCH(E28,'Tasas de Cambio'!$B$11:$B$15,0)),0)} -> 3788.4 | J28: =IFERROR(H28*I28,0) -> 151536 | K28: =IFERROR(J28/'Tasas de Cambio'!$C$5,0) -> 50512 | M28: 27 ago 2026
A29: Comidas | B29: Barcelona | C29: 46513 | D29: cena | E29: EUR | F29: 15 | G29: 3 | H29: 45 | I29: {=IFERROR(INDEX('Tasas de Cambio'!$E$11:$E$15,MATCH(E29,'Tasas de Cambio'!$B$11:$B$15,0)),0)} -> 3788.4 | J29: 170478 | K29: =IFERROR(J29/'Tasas de Cambio'!$C$5,0) -> 56826
A30: Vuelos y Trenes | B30: Italia | C30: 15 May 2027 | D30: Tren Ravenna - Venecia St Lucia | E30: EUR | F30: 25 | G30: 3 | H30: =IFERROR(F30*G30,0) -> 75 | I30: {=IFERROR(INDEX('Tasas de Cambio'!$E$11:$E$15,MATCH(E30,'Tasas de Cambio'!$B$11:$B$15,0)),0)} -> 3788.4 | J30: =IFERROR(H30*I30,0) -> 284130 | K30: =IFERROR(J30/'Tasas de Cambio'!$C$5,0) -> 94710 | L30: Tren regional desde Ravenna hasta Venecia Santa Lucia. https://www.trenitalia.com/en.html | M30: 27 ago 2026
A31: Comidas | B31: Barcelona | C31: 46514 | D31: 3 comidas | E31: EUR | F31: 30 | G31: 3 | H31: 90 | I31: {=IFERROR(INDEX('Tasas de Cambio'!$E$11:$E$15,MATCH(E31,'Tasas de Cambio'!$B$11:$B$15,0)),0)} -> 3788.4 | J31: 340956 | K31: =IFERROR(J31/'Tasas de Cambio'!$C$5,0) -> 113652
A32: Traslados | B32: Barcelona | C32: 46514.0 | D32: Bus, 4 trayectos | E32: EUR | F32: 12 | G32: 3 | H32: =IFERROR(F32*G32,0) -> 36 | I32: {=IFERROR(INDEX('Tasas de Cambio'!$E$11:$E$15,MATCH(E32,'Tasas de Cambio'!$B$11:$B$15,0)),0)} -> 3788.4 | J32: =IFERROR(H32*I32,0) -> 136382.4 | K32: =IFERROR(J32/'Tasas de Cambio'!$C$5,0) -> 45460.8 | M32: 27 ago 2026
A33: Crucero | B33: Mediterráneo | C33: 8 – 15 May (7 noches) | D33: Crucero Barcelona → Ravena — tarifa por persona (cabina) | E33: USD | F33: 670 | G33: 3 | H33: =IFERROR(F33*G33,0) -> 2010 | I33: {=IFERROR(INDEX('Tasas de Cambio'!$E$11:$E$15,MATCH(E33,'Tasas de Cambio'!$B$11:$B$15,0)),0)} -> 3263.4 | J33: =IFERROR(H33*I33,0) -> 6559434 | K33: =IFERROR(J33/'Tasas de Cambio'!$C$5,0) -> 2186478 | L33: Crucero Barcelona-Ravena, 7 noches, incluye propinas. https://www.royalcaribbean.com/lac/es/itinerary/7-night-italy-croatia-cruise-from-barcelona-on-brilliance-BR07M885?sailDate=2027-05-08&packageCode=BR07M885&groupId=BR07BCN-1768961711&country=COL&search=startDate:2027-05-01~2027-05-31 | M33: 27 ago 2026
A34: Traslados | B34: España | C34: 46515 | D34: Traslado hotel → puerto (embarque crucero), Barcelona | E34: EUR | F34: 30 | G34: 1 | H34: 30 | I34: {=IFERROR(INDEX('Tasas de Cambio'!$E$11:$E$15,MATCH(E34,'Tasas de Cambio'!$B$11:$B$15,0)),0)} -> 3788.4 | J34: 113652 | K34: =IFERROR(J34/'Tasas de Cambio'!$C$5,0) -> 37884
A35: Tours y Excursiones | B35: Barcelona | C35: 46515 | D35: N/A | E35: EUR | F35: 0 | G35: 3 | H35: 0 | I35: {=IFERROR(INDEX('Tasas de Cambio'!$E$11:$E$15,MATCH(E35,'Tasas de Cambio'!$B$11:$B$15,0)),0)} -> 3788.4 | J35: 0 | K35: =IFERROR(J35/'Tasas de Cambio'!$C$5,0) -> 0
A36: Comidas | B36: Barcelona | C36: 46515 | D36: desayuno | E36: EUR | F36: 10 | G36: 3 | H36: 30 | I36: {=IFERROR(INDEX('Tasas de Cambio'!$E$11:$E$15,MATCH(E36,'Tasas de Cambio'!$B$11:$B$15,0)),0)} -> 3788.4 | J36: 113652 | K36: =IFERROR(J36/'Tasas de Cambio'!$C$5,0) -> 37884
A37: Tours y Excursiones | B37: Navegacion | C37: 46516 | D37: N/A | E37: EUR | F37: 0 | G37: 3 | H37: 0 | I37: {=IFERROR(INDEX('Tasas de Cambio'!$E$11:$E$15,MATCH(E37,'Tasas de Cambio'!$B$11:$B$15,0)),0)} -> 3788.4 | J37: 0 | K37: =IFERROR(J37/'Tasas de Cambio'!$C$5,0) -> 0
A38: Tours y Excursiones | B38: La Spezia (Florencia/Pisa) | C38: 46517.0 | D38: Panoramic Pisa | E38: USD | F38: 70 | G38: 3 | H38: =IFERROR(F38*G38,0) -> 210 | I38: {=IFERROR(INDEX('Tasas de Cambio'!$E$11:$E$15,MATCH(E38,'Tasas de Cambio'!$B$11:$B$15,0)),0)} -> 3263.4 | J38: =IFERROR(H38*I38,0) -> 685314 | K38: =IFERROR(J38/'Tasas de Cambio'!$C$5,0) -> 228438 | L38: Excursión panorámica por Pisa desde el crucero. https://www.royalcaribbean.com/account/cruise-planner/category/shorex/product/Y8RO?bookingId=3113096&shipCode=BR&sailDate=20270508 | M38: 27 ago 2026
A39: Comidas | B39: La Spezia (Florencia/Pisa) | C39: 46517.0 | D39: Almuerzo en tierra | E39: EUR | F39: 25 | G39: 3 | H39: =IFERROR(F39*G39,0) -> 75 | I39: {=IFERROR(INDEX('Tasas de Cambio'!$E$11:$E$15,MATCH(E39,'Tasas de Cambio'!$B$11:$B$15,0)),0)} -> 3788.4 | J39: =IFERROR(H39*I39,0) -> 284130 | K39: =IFERROR(J39/'Tasas de Cambio'!$C$5,0) -> 94710 | L39: Desayuno y cena incluidos en el crucero, almuerzo en Pisa/Florencia | M39: 28 ago 2026
A40: Tours y Excursiones | B40: Civitavecchia (Roma) | C40: 46518.0 | D40: Visit to Rome | E40: USD | F40: 142 | G40: 3 | H40: =IFERROR(F40*G40,0) -> 426 | I40: {=IFERROR(INDEX('Tasas de Cambio'!$E$11:$E$15,MATCH(E40,'Tasas de Cambio'!$B$11:$B$15,0)),0)} -> 3263.4 | J40: =IFERROR(H40*I40,0) -> 1390208.4 | K40: =IFERROR(J40/'Tasas de Cambio'!$C$5,0) -> 463402.8 | L40: Excursión a Roma desde el crucero. https://www.royalcaribbean.com/account/cruise-planner/category/shorex/product/CV1F?bookingId=3113096&shipCode=BR&sailDate=20270508 | M40: 29 ago 2026
A41: Comidas | B41: Civitavecchia (Roma) | C41: 46518.0 | D41: Almuerzo en tierra | E41: EUR | F41: 25 | G41: 3 | H41: =IFERROR(F41*G41,0) -> 75 | I41: {=IFERROR(INDEX('Tasas de Cambio'!$E$11:$E$15,MATCH(E41,'Tasas de Cambio'!$B$11:$B$15,0)),0)} -> 3788.4 | J41: =IFERROR(H41*I41,0) -> 284130 | K41: =IFERROR(J41/'Tasas de Cambio'!$C$5,0) -> 94710 | L41: Desayuno y cena incluidos en el crucero, almuerzo en Roma | M41: 28 ago 2026
...

Sheet Resumen CZ
B2: RESUMEN DE COTIZACIÓN — EUROPA 2027
B3: 1 de mayo al 16 de mayo de 2027 · 16 días
B5: TOTAL POR CATEGORÍA
B6: Categoría | C6: Total (COP) | D6: Total (USD) | E6: % del total
B7: Vuelos y Trenes | C7: =SUMIF('Crucero y Zurich'!$A:$A,B7,'Crucero y Zurich'!$J:$J) -> 12637329 | D7: =IFERROR(C7/'Tasas de Cambio'!$E$14,0) -> 3926.7704 | E7: =IFERROR(C7/$C$15,0) -> 0.28075104
B8: Traslados | C8: =SUMIF('Crucero y Zurich'!$A:$A,B8,'Crucero y Zurich'!$J:$J) -> 1606218.6 | D8: =IFERROR(C8/'Tasas de Cambio'!$E$14,0) -> 499.0969 | E8: =IFERROR(C8/$C$15,0) -> 0.03568377
B9: Alojamiento | C9: =SUMIF('Crucero y Zurich'!$A:$A,B9,'Crucero y Zurich'!$J:$J) -> 7098252 | D9: =IFERROR(C9/'Tasas de Cambio'!$E$14,0) -> 2205.6248 | E9: =IFERROR(C9/$C$15,0) -> 0.15769485
B10: Crucero | C10: =SUMIF('Crucero y Zurich'!$A:$A,B10,'Crucero y Zurich'!$J:$J) -> 6468682.5 | D10: =IFERROR(C10/'Tasas de Cambio'!$E$14,0) -> 2010 | E10: =IFERROR(C10/$C$15,0) -> 0.14370832
B11: Tours y Excursiones | C11: =SUMIF('Crucero y Zurich'!$A:$A,B11,'Crucero y Zurich'!$J:$J) -> 9876447 | D11: =IFERROR(C11/'Tasas de Cambio'!$E$14,0) -> 3068.8874 | E11: =IFERROR(C11/$C$15,0) -> 0.21941526
B12: Comidas | C12: =SUMIF('Crucero y Zurich'!$A:$A,B12,'Crucero y Zurich'!$J:$J) -> 4475268 | D12: =IFERROR(C12/'Tasas de Cambio'!$E$14,0) -> 1390.5905 | E12: =IFERROR(C12/$C$15,0) -> 0.099422603
B13: Seguro de Viaje | C13: =SUMIF('Crucero y Zurich'!$A:$A,B13,'Crucero y Zurich'!$J:$J) -> 450000 | D13: =IFERROR(C13/'Tasas de Cambio'!$E$14,0) -> 139.82755 | E13: =IFERROR(C13/$C$15,0) -> 0.009997205
B14: Otros y Extras | C14: =SUMIF('Crucero y Zurich'!$A:$A,B14,'Crucero y Zurich'!$J:$J) -> 2400384 | D14: =IFERROR(C14/'Tasas de Cambio'!$E$14,0) -> 745.86623 | E14: =IFERROR(C14/$C$15,0) -> 0.053326958
B15: TOTAL GENERAL | C15: =SUM(C7:C14) -> 45012581 | D15: =SUM(D7:D14) -> 13986.664
B17: COSTO POR PERSONA
B18: Número de personas | C18: ='Tasas de Cambio'!$C$5 -> 3
B19: Costo por persona (COP) | C19: =IFERROR($C$15/'Tasas de Cambio'!$C$5,0) -> 15004194
B20: Costo por persona (USD) | C20: =IFERROR($D$15/'Tasas de Cambio'!$C$5,0) -> 4662.2213
B21: Costo promedio por persona / día (COP) | C21: =IFERROR(C19/16,0) -> 937762.11
B23: TASAS DE CAMBIO UTILIZADAS
B24: Moneda | C24: Tasa a COP
B25: ='Tasas de Cambio'!$B$11 -> EUR | C25: ='Tasas de Cambio'!$E$11 -> 3750.6
B26: ='Tasas de Cambio'!$B$12 -> CHF | C26: ='Tasas de Cambio'!$E$12 -> 4053
B27: ='Tasas de Cambio'!$B$13 -> CZK | C27: ='Tasas de Cambio'!$E$13 -> 155.82
B28: ='Tasas de Cambio'!$B$14 -> USD | C28: ='Tasas de Cambio'!$E$14 -> 3218.25
B29: ='Tasas de Cambio'!$B$15 -> COP | C29: ='Tasas de Cambio'!$E$15 -> 1
B31: Cifras referenciales — sujetas a disponibilidad, temporada y tasa de cambio del día de pago. Documento generado como herramienta de cotización, no constituye una tarifa garantizada.

Sheet Opción 4 (Múnich)
A2: COTIZACIÓN DETALLADA — EUROPA 2027 (01 May – 16 May 2027) — OPCIÓN 4: MÚNICH en vez de ZÚRICH | O2: Vuelos y Trenes | P2: EUR
O3: Traslados | P3: CHF
A4: Categoría | B4: Ciudad / País | C4: Fechas | D4: Concepto / Descripción | E4: Moneda | F4: Costo Unitario (moneda original) | G4: Cantidad | H4: Costo Total (moneda original) | I4: Tasa de Cambio a COP | J4: Costo Total (COP) | K4: Costo por Persona (COP) | L4: Notas | M4: Fecha confirmación precio | O4: Alojamiento | P4: CZK
A5: Tours y Excursiones | B5: Barcelona | C5: 7 May 2027 | D5: Tour Barcelona Modernista | E5: USD | F5: 10 | G5: 3 | H5: =IFERROR(F5*G5,0) -> 30 | I5: {=IFERROR(INDEX('Tasas de Cambio'!$E$11:$E$15,MATCH(E5,'Tasas de Cambio'!$B$11:$B$15,0)),0)} -> 3263.4 | J5: =IFERROR(H5*I5,0) -> 97902 | K5: =IFERROR(J5/'Tasas de Cambio'!$C$5,0) -> 32634 | L5: Tour guiado por el Modernismo catalán en Barcelona. https://www.civitatis.com/es/barcelona/tour-barcelona-modernista/ | M5: 27 ago 2026
A6: Tours y Excursiones | B6: Barcelona | C6: 7 May 2027 | D6: Free tour Sagrada Familia | E6: USD | F6: 10 | G6: 3 | H6: =IFERROR(F6*G6,0) -> 30 | I6: {=IFERROR(INDEX('Tasas de Cambio'!$E$11:$E$15,MATCH(E6,'Tasas de Cambio'!$B$11:$B$15,0)),0)} -> 3263.4 | J6: =IFERROR(H6*I6,0) -> 97902 | K6: =IFERROR(J6/'Tasas de Cambio'!$C$5,0) -> 32634 | L6: Free tour guiado por el exterior de la Sagrada Familia. https://www.civitatis.com/es/barcelona/free-tour-sagrada-familia/ | M6: 27 ago 2026
A7: Otros y Extras | B7: Navegación | C7: 9 May 2027 | D7: Día de navegación | E7: COP | F7: 0 | G7: 1 | H7: =IFERROR(F7*G7,0) -> 0 | I7: {=IFERROR(INDEX('Tasas de Cambio'!$E$11:$E$15,MATCH(E7,'Tasas de Cambio'!$B$11:$B$15,0)),0)} -> 1 | J7: =IFERROR(H7*I7,0) -> 0 | K7: =IFERROR(J7/'Tasas de Cambio'!$C$5,0) -> 0 | L7: Día de navegación, incluido en la tarifa del crucero. https://www.royalcaribbean.com/lac/es/itinerary/7-night-italy-croatia-cruise-from-barcelona-on-brilliance-BR07M885?sailDate=2027-05-08&packageCode=BR07M885&groupId=BR07BCN-1768961711&country=COL&search=startDate:2027-05-01~2027-05-31 | M7: 27 ago 2026
A8: Otros y Extras | B8: Navegación | C8: 13 May 2027 | D8: Día de navegación | E8: COP | F8: 0 | G8: 1 | H8: =IFERROR(F8*G8,0) -> 0 | I8: {=IFERROR(INDEX('Tasas de Cambio'!$E$11:$E$15,MATCH(E8,'Tasas de Cambio'!$B$11:$B$15,0)),0)} -> 1 | J8: =IFERROR(H8*I8,0) -> 0 | K8: =IFERROR(J8/'Tasas de Cambio'!$C$5,0) -> 0 | L8: Día de navegación, incluido en la tarifa del crucero. https://www.royalcaribbean.com/lac/es/itinerary/7-night-italy-croatia-cruise-from-barcelona-on-brilliance-BR07M885?sailDate=2027-05-08&packageCode=BR07M885&groupId=BR07BCN-1768961711&country=COL&search=startDate:2027-05-01~2027-05-31 | M8: 27 ago 2026
A9: Traslados | B9: Venecia | C9: 15 May 2027 | D9: Vaporetti ACTV | E9: EUR | F9: 25 | G9: 3 | H9: =IFERROR(F9*G9,0) -> 75 | I9: {=IFERROR(INDEX('Tasas de Cambio'!$E$11:$E$15,MATCH(E9,'Tasas de Cambio'!$B$11:$B$15,0)),0)} -> 3788.4 | J9: =IFERROR(H9*I9,0) -> 284130 | K9: =IFERROR(J9/'Tasas de Cambio'!$C$5,0) -> 94710 | L9: Boletos de vaporetto (transporte acuático) por Venecia. https://book.tickets-venice.com/es/book/8748/select/?_gl=1%2A1073ils%2A_gcl_aw%2AR0NMLjE3ODc4NzgwODMuRUFJYUlRb2JDaE1JaFpPNjdZekNsZ01Wd1lSYUJSM2Y1U1JPRUFBWUF5QUFFZ0tjeFBEX0J3RQ..%2A_gcl_au%2ANzIxMTA1MTQ5LjE3ODc4NzgwODMuLS4tLjE3ODc4NzgwODMuMTE2MDU2ODc1MS4xNzg3ODc4MDg0LjE3ODc4NzgwODM.%2A_ga%2ANDcyOTU3MzYyLjE3ODc4NzgwODM.%2A_ga_Y45PC9R73C%2AczE3ODc4NzgwODMkbzEkZzAkdDE3ODc4NzgwODQkajU5JGwwJGgw&cookieBanner=false&date=2027-05-15&tourId=15560&variantId=15560 | M9: 27 ago 2026
A10: Otros y Extras | C10: Durante el viaje | D10: SIM card de viaje (datos internacionales) | E10: USD | F10: 52 | G10: 1 | H10: 52 | I10: {=IFERROR(INDEX('Tasas de Cambio'!$E$11:$E$15,MATCH(E10,'Tasas de Cambio'!$B$11:$B$15,0)),0)} -> 3263.4 | J10: 169696.8 | K10: =IFERROR(J10/'Tasas de Cambio'!$C$5,0) -> 56565.6 | L10: SIM compartida entre las 3 personas para los 16 días del viaje. https://esim.holafly.com/es/esim-europa/?selectedDays=16&startDate=2027-05-01&endDate=2027-05-16 | M10: 27 ago 2026
A11: Otros y Extras | C11: Contingencia | D11: Imprevistos / gastos varios (contingencia) | E11: EUR | F11: 200 | G11: 3 | H11: 600 | I11: {=IFERROR(INDEX('Tasas de Cambio'!$E$11:$E$15,MATCH(E11,'Tasas de Cambio'!$B$11:$B$15,0)),0)} -> 3788.4 | J11: 2273040 | K11: =IFERROR(J11/'Tasas de Cambio'!$C$5,0) -> 757680
A12: Vuelos y Trenes | B12: Bogota / Múnich | C12: 46507 | D12: Vuelo internacional Bogotá → Múnich (ida) | E12: COP | F12: 1435635 | G12: 3 | H12: 4306905 | I12: {=IFERROR(INDEX('Tasas de Cambio'!$E$11:$E$15,MATCH(E12,'Tasas de Cambio'!$B$11:$B$15,0)),0)} -> 1 | J12: 4306905 | K12: =IFERROR(J12/'Tasas de Cambio'!$C$5,0) -> 1435635 | L12: Lufthansa, sale vie 30 abr 23:30 BOG, llega sáb 1 may 20:10 MUC (+1 día, vía FRA, 2h05m), 13h40m total, Economy Light. Total ida+regreso $2.871.270 COP/persona, dividido entre los 2 tramos.
A13: Traslados | B13: Alemania | C13: 46508 | D13: Traslado aeropuerto → hotel, Múnich | E13: EUR | F13: 75 | G13: 1 | H13: 75 | I13: {=IFERROR(INDEX('Tasas de Cambio'!$E$11:$E$15,MATCH(E13,'Tasas de Cambio'!$B$11:$B$15,0)),0)} -> 3788.4 | J13: 284130 | K13: =IFERROR(J13/'Tasas de Cambio'!$C$5,0) -> 94710 | L13: Estimado: Uber X/taxi, aeropuerto MUC → centro, ~45 min, €70-90 (1 carro para el grupo).
A14: Alojamiento | B14: Múnich, Alemania | C14: 1 May – 6 May (5 noches) | D14: Hotel Múnich — costo por noche | E14: EUR | F14: 130 | G14: 5 | H14: =IFERROR(F14*G14,0) -> 650 | I14: {=IFERROR(INDEX('Tasas de Cambio'!$E$11:$E$15,MATCH(E14,'Tasas de Cambio'!$B$11:$B$15,0)),0)} -> 3788.4 | J14: =IFERROR(H14*I14,0) -> 2462460 | K14: =IFERROR(J14/'Tasas de Cambio'!$C$5,0) -> 820820 | L14: Recomendado: Eden Hotel Wolff, cerca de la Estación Central, ~10-15 min a Marienplatz. €130/noche aprox. | M14: 27 ago 2026
A15: Seguro de Viaje | B15: Internacional | C15: 1 – 16 may 2027 (16 días de cobertura) | D15: Asistencia médica internacional | E15: COP | F15: 295980 | G15: 3 | H15: =IFERROR(F15*G15,0) -> 887940 | I15: {=IFERROR(INDEX('Tasas de Cambio'!$E$11:$E$15,MATCH(E15,'Tasas de Cambio'!$B$11:$B$15,0)),0)} -> 1 | J15: =IFERROR(H15*I15,0) -> 887940 | K15: =IFERROR(J15/'Tasas de Cambio'!$C$5,0) -> 295980 | L15: Asistencia médica internacional, cobertura USD 60.000 (Cuponatic). https://www.cuponatic.com.co/descuento/asistencia-medica-internacional-cobertura-de-usd-60-000?m=tarjetas-de-asistencia&id_descuento=212587 | M15: 27 ago 2026
A16: Tours y Excursiones | B16: Múnich | C16: 1 May 2027 | D16: Zugspitze, Eibsee, Highline179 & Neuschwanstein Tour (privado) | E16: COP | F16: 2690900 | G16: 1 | H16: 2690900 | I16: {=IFERROR(INDEX('Tasas de Cambio'!$E$11:$E$15,MATCH(E16,'Tasas de Cambio'!$B$11:$B$15,0)),0)} -> 1 | J16: 2690900 | K16: =IFERROR(J16/'Tasas de Cambio'!$C$5,0) -> 896966.67 | L16: Tour privado 12h, guía en inglés, dom 2 may 8:00am, para el grupo de 3. Incluye Zugspitze, lago Eibsee, puente Highline179 y Castillo de Neuschwanstein. Col$2.690.900 total (3 participantes).
A18: Comidas | B18: Múnich | C18: 46509.0 | D18: Comida del día (desayuno, almuerzo y cena) | E18: EUR | F18: 52 | G18: 3 | H18: =IFERROR(F18*G18,0) -> 156 | I18: {=IFERROR(INDEX('Tasas de Cambio'!$E$11:$E$15,MATCH(E18,'Tasas de Cambio'!$B$11:$B$15,0)),0)} -> 3788.4 | J18: =IFERROR(H18*I18,0) -> 590990.4 | K18: =IFERROR(J18/'Tasas de Cambio'!$C$5,0) -> 196996.8 | L18: Estimado: ~€52/persona/día (desayuno+almuerzo+cena) | M18: 28 ago 2026
A19: Tours y Excursiones | B19: Múnich | C19: 46510 | D19: Excursión de un día a Salzburgo, Austria | E19: EUR | F19: 85 | G19: 3 | H19: 255 | I19: {=IFERROR(INDEX('Tasas de Cambio'!$E$11:$E$15,MATCH(E19,'Tasas de Cambio'!$B$11:$B$15,0)),0)} -> 3788.4 | J19: 966042 | K19: =IFERROR(J19/'Tasas de Cambio'!$C$5,0) -> 322014 | L19: Recomendado: tour guiado en tren, incluye transporte + guía. https://www.getyourguide.com/munich-l26/salzburg-day-trip-from-munich-by-train-t24230/
A20: Comidas | B20: Múnich | C20: 46510.0 | D20: Comida del día (desayuno, almuerzo y cena) | E20: EUR | F20: 52 | G20: 3 | H20: =IFERROR(F20*G20,0) -> 156 | I20: {=IFERROR(INDEX('Tasas de Cambio'!$E$11:$E$15,MATCH(E20,'Tasas de Cambio'!$B$11:$B$15,0)),0)} -> 3788.4 | J20: =IFERROR(H20*I20,0) -> 590990.4 | K20: =IFERROR(J20/'Tasas de Cambio'!$C$5,0) -> 196996.8 | L20: Estimado: ~€52/persona/día (desayuno+almuerzo+cena) | M20: 28 ago 2026
A21: Tours y Excursiones | B21: Múnich | C21: 46511 | D21: Museo BMW + Parque Olímpico | E21: EUR | F21: 25 | G21: 3 | H21: 75 | I21: {=IFERROR(INDEX('Tasas de Cambio'!$E$11:$E$15,MATCH(E21,'Tasas de Cambio'!$B$11:$B$15,0)),0)} -> 3788.4 | J21: 284130 | K21: =IFERROR(J21/'Tasas de Cambio'!$C$5,0) -> 94710 | L21: Recomendado: entrada museo + parque. https://www.getyourguide.com/bmw-museum-l3579/
A22: Comidas | B22: Múnich | C22: 46511.0 | D22: Comida del día (desayuno, almuerzo y cena) | E22: EUR | F22: 52 | G22: 3 | H22: =IFERROR(F22*G22,0) -> 156 | I22: {=IFERROR(INDEX('Tasas de Cambio'!$E$11:$E$15,MATCH(E22,'Tasas de Cambio'!$B$11:$B$15,0)),0)} -> 3788.4 | J22: =IFERROR(H22*I22,0) -> 590990.4 | K22: =IFERROR(J22/'Tasas de Cambio'!$C$5,0) -> 196996.8 | L22: Estimado: ~€52/persona/día (desayuno+almuerzo+cena) | M22: 28 ago 2026
A23: Comidas | B23: Múnich | C23: 46512.0 | D23: Comida del día (desayuno, almuerzo y cena) | E23: EUR | F23: 52 | G23: 3 | H23: =IFERROR(F23*G23,0) -> 156 | I23: {=IFERROR(INDEX('Tasas de Cambio'!$E$11:$E$15,MATCH(E23,'Tasas de Cambio'!$B$11:$B$15,0)),0)} -> 3788.4 | J23: =IFERROR(H23*I23,0) -> 590990.4 | K23: =IFERROR(J23/'Tasas de Cambio'!$C$5,0) -> 196996.8 | L23: Estimado: ~€52/persona/día (desayuno+almuerzo+cena) | M23: 28 ago 2026
A24: Alojamiento | B24: Barcelona, España | C24: 6 – 8 May (2 noches, pre-crucero) | D24: Hotel Barcelona — costo total (2 noches) | E24: COP | F24: 1900000 | G24: 1 | H24: =IFERROR(F24*G24,0) -> 1900000 | I24: {=IFERROR(INDEX('Tasas de Cambio'!$E$11:$E$15,MATCH(E24,'Tasas de Cambio'!$B$11:$B$15,0)),0)} -> 1 | J24: =IFERROR(H24*I24,0) -> 1900000 | K24: =IFERROR(J24/'Tasas de Cambio'!$C$5,0) -> 633333.33 | L24: Sagrada Familia, 2 noches (6-8 may). https://www.booking.com/hotel/es/sagradafamilia.es.html?aid=2311236&label=es-co-booking-desktop-vjGZbEFOhRc3a9njxeT3IwS652829002024%3Apl%3Ata%3Ap1%3Ap2%3Aac%3Aap%3Aneg%3Afi%3Atikwd-65526620%3Alp9246960%3Ali%3Adec%3Adm&sid=f6a1a9bb810c453f7b5f1225205f1f26&all_sr_blocks=9118812_91908190_0_2_0&checkin=2027-05-06&checkout=2027-05-08&dest_id=-372490&dest_type=city&dist=0&group_adults=3&group_children=0&hapos=1&highlighted_blocks=9118812_91908190_0_2_0&hpos=1&matching_block_id=9118812_91908190_0_2_0&no_rooms=1&req_adults=3&req_children=0&room1=A%2CA%2CA&sb_price_type=total&sr_order=popularity&sr_pri_blocks=9118812_91908190_0_2_0__37600&srepoch=1787875557&srpvid=a2d600b07c230149&type=total&ucfs=1 | M24: 27 ago 2026
A25: Vuelos y Trenes | B25: Múnich / Barcelona | C25: 46513 | D25: Vuelo Múnich → Barcelona, directo | E25: EUR | F25: 156.97 | G25: 3 | H25: 470.91 | I25: {=IFERROR(INDEX('Tasas de Cambio'!$E$11:$E$15,MATCH(E25,'Tasas de Cambio'!$B$11:$B$15,0)),0)} -> 3788.4 | J25: 1783995.4 | K25: =IFERROR(J25/'Tasas de Cambio'!$C$5,0) -> 594665.15 | L25: Lufthansa City Airlines, jue 6 may 06:15 MUC → 08:25 BCN, directo, 2h10m, Economy Basic. Asumido por persona (confirmar si es total).
A26: Traslados | B26: Alemania | C26: 46513 | D26: Traslado hotel → aeropuerto, Múnich | E26: EUR | F26: 75 | G26: 1 | H26: 75 | I26: {=IFERROR(INDEX('Tasas de Cambio'!$E$11:$E$15,MATCH(E26,'Tasas de Cambio'!$B$11:$B$15,0)),0)} -> 3788.4 | J26: 284130 | K26: =IFERROR(J26/'Tasas de Cambio'!$C$5,0) -> 94710 | L26: Estimado: Uber X/taxi, centro → aeropuerto MUC, ~45 min, €70-90 (1 carro para el grupo).
A27: Traslados | B27: España | C27: 46513.0 | D27: Traslado aeropuerto → hotel, Barcelona | E27: EUR | F27: 40 | G27: 1 | H27: =IFERROR(F27*G27,0) -> 40 | I27: {=IFERROR(INDEX('Tasas de Cambio'!$E$11:$E$15,MATCH(E27,'Tasas de Cambio'!$B$11:$B$15,0)),0)} -> 3788.4 | J27: =IFERROR(H27*I27,0) -> 151536 | K27: =IFERROR(J27/'Tasas de Cambio'!$C$5,0) -> 50512 | M27: 27 ago 2026
A28: Comidas | B28: Barcelona | C28: 46513 | D28: cena | E28: EUR | F28: 15 | G28: 3 | H28: 45 | I28: {=IFERROR(INDEX('Tasas de Cambio'!$E$11:$E$15,MATCH(E28,'Tasas de Cambio'!$B$11:$B$15,0)),0)} -> 3788.4 | J28: 170478 | K28: =IFERROR(J28/'Tasas de Cambio'!$C$5,0) -> 56826
A29: Vuelos y Trenes | B29: Italia | C29: 15 May 2027 | D29: Tren Ravenna - Venecia St Lucia | E29: EUR | F29: 25 | G29: 3 | H29: =IFERROR(F29*G29,0) -> 75 | I29: {=IFERROR(INDEX('Tasas de Cambio'!$E$11:$E$15,MATCH(E29,'Tasas de Cambio'!$B$11:$B$15,0)),0)} -> 3788.4 | J29: =IFERROR(H29*I29,0) -> 284130 | K29: =IFERROR(J29/'Tasas de Cambio'!$C$5,0) -> 94710 | L29: Tren regional desde Ravenna hasta Venecia Santa Lucia. https://www.trenitalia.com/en.html | M29: 27 ago 2026
