Workbook

Sheet Resumen
A1: PLAN DISNEY WORLD + UNIVERSAL + EPIC UNIVERSE — SEMANA SANTA 2027
A3: Fechas | B3: Sáb 20 mar 2027 → Dom 28 mar 2027 (8 noches)
A4: Origen | B4: Bogotá (BOG) → Orlando (MCO)
A5: Grupo total | B5: 8 personas: 5 adultos + niños de 13, 9 y 7 años
A6: Tasa de cambio (TRM aprox.) | B6: 3120 | C6: Banco de la República, TRM ~sep-2026. Fluctúa a diario — ajustar antes de usar.
A8: COMPOSICIÓN DE LOS 2 GRUPOS / HABITACIONES
B9: Grupo A — Hab. 2 | D9: Grupo B — Hab. 1
A10: Integrantes | B10: 3 adultos + niño de 7 años | D10: 2 adultos + niños de 9 y 13 años
A12: RESUMEN DE COSTOS POR GRUPO (USD)
A13: Concepto | B13: Grupo A (USD) | C13: Grupo B (USD) | D13: TOTAL (USD) | E13: Link de reserva
A14: Vuelos (Bogotá ⇄ Orlando) | B14: ='Grupo A'!E9 -> 2720 | C14: ='Grupo B'!E9 -> 2720 | D14: =B14+C14 -> 5440 | E14: Avianca — reservar
A15: Hotel (8 noches, DoubleTree Suites) | B15: ='Grupo A'!F15 -> 2560 | C15: ='Grupo B'!F15 -> 2560 | D15: =B15+C15 -> 5120 | E15: DoubleTree — reservar
A16: Tickets Disney World (4 días) | B16: ='Grupo A'!E22 -> 3073.09 | C16: ='Grupo B'!E22 -> 3073.09 | D16: =B16+C16 -> 6146.18 | E16: Disney — comprar tickets
A17: Tickets Universal (Studios+IOA, 1 día) | B17: ='Grupo A'!E29 -> 947.05 | C17: ='Grupo B'!E29 -> 947.05 | D17: =B17+C17 -> 1894.1 | E17: Universal — comprar tickets
A18: Tickets Epic Universe (1 día) | B18: ='Grupo A'!E36 -> 818.89 | C18: ='Grupo B'!E36 -> 818.89 | D18: =B18+C18 -> 1637.78 | E18: Universal — Epic Universe
A19: Comida (8 días) | B19: ='Grupo A'!E42 -> 1600 | C19: ='Grupo B'!E42 -> 1600 | D19: =B19+C19 -> 3200
A20: Transporte local / extras | B20: ='Grupo A'!B50 -> 480 | C20: ='Grupo B'!B50 -> 480 | D20: =B20+C20 -> 960
A21: TOTAL POR GRUPO (USD) | B21: =SUM(B14:B20) -> 12199.03 | C21: =SUM(C14:C20) -> 12199.03 | D21: =B21+C21 -> 24398.06
A23: MISMO RESUMEN EN PESOS COLOMBIANOS (COP)
A24: Concepto | B24: Grupo A (COP) | C24: Grupo B (COP) | D24: TOTAL (COP)
A25: Vuelos (Bogotá ⇄ Orlando) | B25: =B14*$B$6 -> 8486400 | C25: =C14*$B$6 -> 8486400 | D25: =D14*$B$6 -> 16972800
A26: Hotel (8 noches, DoubleTree Suites) | B26: =B15*$B$6 -> 7987200 | C26: =C15*$B$6 -> 7987200 | D26: =D15*$B$6 -> 15974400
A27: Tickets Disney World (4 días) | B27: =B16*$B$6 -> 9588040.8 | C27: =C16*$B$6 -> 9588040.8 | D27: =D16*$B$6 -> 19176082
A28: Tickets Universal (Studios+IOA, 1 día) | B28: =B17*$B$6 -> 2954796 | C28: =C17*$B$6 -> 2954796 | D28: =D17*$B$6 -> 5909592
A29: Tickets Epic Universe (1 día) | B29: =B18*$B$6 -> 2554936.8 | C29: =C18*$B$6 -> 2554936.8 | D29: =D18*$B$6 -> 5109873.6
A30: Comida (8 días) | B30: =B19*$B$6 -> 4992000 | C30: =C19*$B$6 -> 4992000 | D30: =D19*$B$6 -> 9984000
A31: Transporte local / extras | B31: =B20*$B$6 -> 1497600 | C31: =C20*$B$6 -> 1497600 | D31: =D20*$B$6 -> 2995200
A32: TOTAL POR GRUPO (COP) | B32: =SUM(B25:B31) -> 38060974 | C32: =SUM(C25:C31) -> 38060974 | D32: =B32+C32 -> 76121947
A34: Costo por persona — Grupo A (÷4) | B34: =B21/4 -> 3049.7575 | C34: =B32/4 -> 9515243.4
A35: Costo por persona — Grupo B (÷4) | B35: =C21/4 -> 3049.7575 | C35: =C32/4 -> 9515243.4
A37: TOTAL VIAJE — 8 PERSONAS — EN DÓLARES (USD) | D37: =D21 -> 24398.06
A38: TOTAL VIAJE — 8 PERSONAS — EN PESOS COLOMBIANOS (COP) | D38: =D32 -> 76121947
A40: Links de reserva rápida
A41: Vuelos Avianca Bogotá-Orlando | B41: Abrir →
A42: Hotel DoubleTree Suites | B42: Abrir →
A43: Tickets Disney World | B43: Abrir →
A44: Tickets Universal Studios + Islands of Adventure | B44: Abrir →
A45: Tickets Universal Epic Universe | B45: Abrir →
A47: Notas y fuentes
A48: • Se agregó un día completo en Universal Epic Universe (4to parque de Universal, abierto desde mayo 2025), separado del día de Universal Studios + Islands of Adventure.
...

Sheet Grupo A
A1: PRESUPUESTO — GRUPO A — 3 adultos + niño de 7 años (Habitación 2)
A2: Habitación 2: 3 adultos + niño de 7 años
A4: VUELOS — Bogotá (BOG) ⇄ Orlando (MCO)
A5: Persona | B5: Edad/tipo | C5: Ida+Vuelta (USD) | D5: Cant. | E5: Subtotal | F5: Reserva
A6: Adultos (incluye 13 años si aplica) | B6: Adulto | C6: 680 | D6: 3 | E6: =C6*D6 -> 2040 | F6: Avianca — reservar
A7: Niños | B7: Niño (7) | C7: 680 | D7: 1 | E7: =C7*D7 -> 680 | F7: Avianca — reservar
A8: Nota: Avianca publica tarifa 'desde' $505/tramo en ruta actual BOG-MCO; Frontier lanza vuelo directo diario desde mar-2027. Estimamos $680 pp ida+vuelta para temporada pico (Semana Santa).
A9: SUBTOTAL VUELOS | E9: =E6+E7 -> 2720
A11: HOTEL — DoubleTree Suites by Hilton, Disney Springs Area (1-Bedroom Suite)
A12: Concepto | B12: Tarifa/noche | C12: Adultos extra | D12: Cargo extra/noche | E12: Noches | F12: Subtotal
A13: 1-Bedroom Suite (king/2 queens + sofá cama) — Habitación 2: 3 adultos + niño de 7 años | B13: 320 | C13: 0 | D13: 0 | E13: 8 | F13: =(B13+D13)*E13 -> 2560
A14: Hotel oficial 'Disney Springs Resort Area' (Good Neighbor): aunque no es propiedad de Disney, incluye shuttle GRATIS a los 4 parques Disney + early park access, igual que un resort Disney — no necesita Uber para esos días. Calificación 8.2/10 'Muy bueno' (921 reseñas), 4 estrellas. Tarifa pico estimada sobre base $98-169/noche fuera de temporada alta (Kayak/Priceline). Suite duerme hasta 4-5. | F14: DoubleTree — reservar
A15: SUBTOTAL HOTEL (8 noches) | F15: =F13 -> 2560
A17: TICKETS DISNEY WORLD — 4 días, 1 parque/día, sin Park Hopper
A18: Persona | B18: Edad/tipo | C18: Precio unit. | D18: Cant. | E18: Subtotal | F18: Reserva
A19: Adultos (10+, incluye 13 años) | B19: Adulto | C19: 773.12 | D19: 3 | E19: =C19*D19 -> 2319.36 | F19: Disney — comprar
A20: Niños (3-9) | B20: Niño (7) | C20: 753.73 | D20: 1 | E20: =C20*D20 -> 753.73 | F20: Disney — comprar
A21: Fuente: tabla oficial de temporada pico (MouseSavers). El de 13 años paga tarifa adulto (10+).
A22: SUBTOTAL TICKETS DISNEY | E22: =E19+E20 -> 3073.09
A24: TICKETS UNIVERSAL — Studios + Islands of Adventure, 1 día Park-to-Park
A25: Persona | B25: Edad/tipo | C25: Precio unit. | D25: Cant. | E25: Subtotal | F25: Reserva
A26: Adultos (incluye 13 años) | B26: Adulto | C26: 238.55 | D26: 3 | E26: =C26*D26 -> 715.65 | F26: Universal — comprar
A27: Niños | B27: Niño (7) | C27: 231.4 | D27: 1 | E27: =C27*D27 -> 231.4 | F27: Universal — comprar
A28: Fuente: Undercover Tourist, 1-Day 2-Park Park-to-Park. No incluye Epic Universe (ticket aparte abajo).
A29: SUBTOTAL TICKETS UNIVERSAL | E29: =E26+E27 -> 947.05
A31: TICKETS EPIC UNIVERSE — 1 día, 1 parque
A32: Persona | B32: Edad/tipo | C32: Precio unit. | D32: Cant. | E32: Subtotal | F32: Reserva
A33: Adultos (incluye 13 años) | B33: Adulto | C33: 206.27 | D33: 3 | E33: =C33*D33 -> 618.81 | F33: Epic Universe — comprar
A34: Niños | B34: Niño (7) | C34: 200.08 | D34: 1 | E34: =C34*D34 -> 200.08 | F34: Epic Universe — comprar
A35: Fuente: ticket oficial 1-Day Epic Universe observado a $206.27 adulto (dato real, fecha no-pico); en Semana Santa puede ser más alto. Niño estimado a ~97% del adulto (ratio Universal).
A36: SUBTOTAL TICKETS EPIC UNIVERSE | E36: =E33+E34 -> 818.89
A38: COMIDA — 8 días
A39: Concepto | B39: Costo/persona/día | C39: Personas | E39: Subtotal 8 días
A40: Adultos (incluye 13 años) | B40: 55 | C40: 3 | E40: =B40*C40*8 -> 1320
A41: Niños | B41: 35 | C41: 1 | E41: =B41*C41*8 -> 280
A42: SUBTOTAL COMIDA | E42: =E40+E41 -> 1600
A44: TRANSPORTE LOCAL Y EXTRAS
A45: Concepto | B45: Costo (USD)
A46: Uber/taxi ida y vuelta — Universal + Epic Universe (2 días; Disney va en shuttle gratis) | B46: 70
A47: PhotoPass / fotos | B47: 110
...

Sheet Grupo B
A1: PRESUPUESTO — GRUPO B — 2 adultos + niños de 9 y 13 años (Habitación 1)
A2: Habitación 1: 2 adultos + niños de 9 y 13 años
A4: VUELOS — Bogotá (BOG) ⇄ Orlando (MCO)
A5: Persona | B5: Edad/tipo | C5: Ida+Vuelta (USD) | D5: Cant. | E5: Subtotal | F5: Reserva
A6: Adultos (incluye 13 años si aplica) | B6: Adulto | C6: 680 | D6: 3 | E6: =C6*D6 -> 2040 | F6: Avianca — reservar
A7: Niños | B7: Niño (9); 13 años = tarifa adulto | C7: 680 | D7: 1 | E7: =C7*D7 -> 680 | F7: Avianca — reservar
A8: Nota: Avianca publica tarifa 'desde' $505/tramo en ruta actual BOG-MCO; Frontier lanza vuelo directo diario desde mar-2027. Estimamos $680 pp ida+vuelta para temporada pico (Semana Santa).
A9: SUBTOTAL VUELOS | E9: =E6+E7 -> 2720
A11: HOTEL — DoubleTree Suites by Hilton, Disney Springs Area (1-Bedroom Suite)
A12: Concepto | B12: Tarifa/noche | C12: Adultos extra | D12: Cargo extra/noche | E12: Noches | F12: Subtotal
A13: 1-Bedroom Suite (king/2 queens + sofá cama) — Habitación 1: 2 adultos + niños de 9 y 13 años | B13: 320 | C13: 0 | D13: 0 | E13: 8 | F13: =(B13+D13)*E13 -> 2560
A14: Hotel oficial 'Disney Springs Resort Area' (Good Neighbor): aunque no es propiedad de Disney, incluye shuttle GRATIS a los 4 parques Disney + early park access, igual que un resort Disney — no necesita Uber para esos días. Calificación 8.2/10 'Muy bueno' (921 reseñas), 4 estrellas. Tarifa pico estimada sobre base $98-169/noche fuera de temporada alta (Kayak/Priceline). Suite duerme hasta 4-5. | F14: DoubleTree — reservar
A15: SUBTOTAL HOTEL (8 noches) | F15: =F13 -> 2560
A17: TICKETS DISNEY WORLD — 4 días, 1 parque/día, sin Park Hopper
A18: Persona | B18: Edad/tipo | C18: Precio unit. | D18: Cant. | E18: Subtotal | F18: Reserva
A19: Adultos (10+, incluye 13 años) | B19: Adulto | C19: 773.12 | D19: 3 | E19: =C19*D19 -> 2319.36 | F19: Disney — comprar
A20: Niños (3-9) | B20: Niño (9); 13 años = tarifa adulto | C20: 753.73 | D20: 1 | E20: =C20*D20 -> 753.73 | F20: Disney — comprar
A21: Fuente: tabla oficial de temporada pico (MouseSavers). El de 13 años paga tarifa adulto (10+).
A22: SUBTOTAL TICKETS DISNEY | E22: =E19+E20 -> 3073.09
A24: TICKETS UNIVERSAL — Studios + Islands of Adventure, 1 día Park-to-Park
A25: Persona | B25: Edad/tipo | C25: Precio unit. | D25: Cant. | E25: Subtotal | F25: Reserva
A26: Adultos (incluye 13 años) | B26: Adulto | C26: 238.55 | D26: 3 | E26: =C26*D26 -> 715.65 | F26: Universal — comprar
A27: Niños | B27: Niño (9); 13 años = tarifa adulto | C27: 231.4 | D27: 1 | E27: =C27*D27 -> 231.4 | F27: Universal — comprar
A28: Fuente: Undercover Tourist, 1-Day 2-Park Park-to-Park. No incluye Epic Universe (ticket aparte abajo).
A29: SUBTOTAL TICKETS UNIVERSAL | E29: =E26+E27 -> 947.05
A31: TICKETS EPIC UNIVERSE — 1 día, 1 parque
A32: Persona | B32: Edad/tipo | C32: Precio unit. | D32: Cant. | E32: Subtotal | F32: Reserva
A33: Adultos (incluye 13 años) | B33: Adulto | C33: 206.27 | D33: 3 | E33: =C33*D33 -> 618.81 | F33: Epic Universe — comprar
A34: Niños | B34: Niño (9); 13 años = tarifa adulto | C34: 200.08 | D34: 1 | E34: =C34*D34 -> 200.08 | F34: Epic Universe — comprar
A35: Fuente: ticket oficial 1-Day Epic Universe observado a $206.27 adulto (dato real, fecha no-pico); en Semana Santa puede ser más alto. Niño estimado a ~97% del adulto (ratio Universal).
A36: SUBTOTAL TICKETS EPIC UNIVERSE | E36: =E33+E34 -> 818.89
A38: COMIDA — 8 días
A39: Concepto | B39: Costo/persona/día | C39: Personas | E39: Subtotal 8 días
A40: Adultos (incluye 13 años) | B40: 55 | C40: 3 | E40: =B40*C40*8 -> 1320
A41: Niños | B41: 35 | C41: 1 | E41: =B41*C41*8 -> 280
A42: SUBTOTAL COMIDA | E42: =E40+E41 -> 1600
A44: TRANSPORTE LOCAL Y EXTRAS
A45: Concepto | B45: Costo (USD)
A46: Uber/taxi ida y vuelta — Universal + Epic Universe (2 días; Disney va en shuttle gratis) | B46: 70
A47: PhotoPass / fotos | B47: 110
...

Sheet Itinerario Grupo A
A1: ITINERARIO — Grupo A — 3 adultos + niño de 7 años
A2: Habitación 2: 3 adultos + niño de 7 años. Ritmo tranquilo, atracciones sin restricción de altura como base.
A4: Día | B4: Fecha | C4: Parque / Actividad | D4: Plan recomendado para este subgrupo | E4: Nota de altura/edad
A5: 1 | B5: Sáb 20 mar | C5: Llegada + check-in | D5: Día libre en familia — pileta del resort, Disney Springs, descanso. Sin plan de parque.
A6: 2 | B6: Dom 21 mar | C6: Magic Kingdom | D6: • Mañana: Seven Dwarfs Mine Train (38"), Peter Pan's Flight, Jungle Cruise, it's a small world • Mediodía: Casey Jr. Splash 'N' Soak, almuerzo en Main Street • Tarde: The Barnstormer (35"), Philharmonic, Enchanted Tiki Room • Noche: desfile / fuegos artificiales desde Main Street | E6: Mayoría de atracciones de MK no tienen requisito de altura.
A7: 3 | B7: Lun 22 mar | C7: EPCOT | D7: • Mañana: Frozen Ever After, The Seas with Nemo & Friends, Turtle Talk with Crush • Mediodía: Journey of Water, Kidcot stops en World Showcase • Tarde: Recorrido por pabellones, snacks internacionales • Evitar: Guardians of the Galaxy (42"), Test Track (40") salvo que el niño llegue a esa altura | E7: Frozen Ever After y The Seas no tienen requisito de altura.
A8: 4 | B8: Mar 23 mar | C8: Universal Studios + Islands of Adventure | D8: • Mañana: Camp Jurassic, Caro-Seuss-el, Cat in the Hat (36"), One Fish Two Fish • Mediodía: Wizarding World Hogsmeade (tienda de varitas, Butterbeer) • Tarde: Hogwarts Express (sin restricción), show de personajes • Nota: Hagrid's (48") y VelociCoaster (51") no disponibles para 7 años típico | E8: Universal es más intenso que Disney en general.
A9: 5 | B9: Mié 24 mar | C9: Hollywood Studios | D9: • Mañana: Slinky Dog Dash (38"), Toy Story Mania • Mediodía: Mickey and Minnie's Runaway Railway, Muppets Vision 3D • Tarde: Star Tours, Disney Junior show • Noche: Fantasmic (si el horario lo permite) | E9: Toy Story Land es el sector ideal para esta edad.
A10: 6 | B10: Jue 25 mar | C10: Universal Epic Universe | D10: • Mañana: Yoshi's Adventure (34", sin acompañante), Mine-Cart Madness (36"/48" solo) • Mediodía: Constellation Carousel (sin restricción), Dragon Racer's Rally (36") • Tarde: Fyre Drill (sin restricción, se mojan), Power-Up Bands interactivas en Super Nintendo World • Evitar: Stardust Racers (42"), Monsters Unchained (48"), Hiccup's Wing Gliders (40") | E10: Super Nintendo World e Isle of Berk son las zonas más accesibles del parque para 7 años.
A11: 7 | B11: Vie 26 mar | C11: Animal Kingdom | D11: • Mañana: Kilimanjaro Safaris (sin restricción), Na'vi River Journey (sin restricción) • Mediodía: The Boneyard, Finding Nemo show • Tarde: Gorilla Falls / Maharajah Jungle Trek, Festival of the Lion King • Si mide 44"+: Avatar Flight of Passage junto al Grupo B | E11: Uno de los mejores parques para esta edad.
A12: 8 | B12: Sáb 27 mar | C12: Día libre / compras / pileta | D12: Día libre en familia — pileta del resort, Disney Springs, descanso. Sin plan de parque.
B13: Dom 28 mar | C13: Check-out + vuelo a Bogotá | D13: Check-out, traslado al aeropuerto, vuelo de regreso a Bogotá.
A15: Fuentes: alturas mínimas según Disney/Universal (TouringPlans, MagicGuides, ThrillZing, NBC Insider, DeepArrival — consultadas sep-2026). Verificar altura real de cada niño antes del viaje.

Sheet Itinerario Grupo B
A1: ITINERARIO — Grupo B — 2 adultos + niños de 9 y 13 años
A2: Habitación 1: 2 adultos + niños de 9 y 13 años. Más thrill rides; el de 13 con creciente autonomía.
A4: Día | B4: Fecha | C4: Parque / Actividad | D4: Plan recomendado para este subgrupo | E4: Nota de altura/edad
A5: 1 | B5: Sáb 20 mar | C5: Llegada + check-in | D5: Día libre en familia — pileta del resort, Disney Springs, descanso. Sin plan de parque.
A6: 2 | B6: Dom 21 mar | C6: Magic Kingdom | D6: • Mañana: Space Mountain (44"), TRON Lightcycle / Run (48"), Big Thunder Mountain • Mediodía: Seven Dwarfs Mine Train, Pirates of the Caribbean, Haunted Mansion • Tarde: Tiana's Bayou Adventure (40"), Tomorrowland Speedway (13 años puede manejar solo, 54") • Noche: fuegos artificiales cerca del castillo | E6: TRON requiere 48" — verificar altura del de 9 años.
A7: 3 | B7: Lun 22 mar | C7: EPCOT | D7: • Mañana: Guardians of the Galaxy: Cosmic Rewind (42"), Test Track (40") • Mediodía: Mission: SPACE, Soarin' • Tarde: World Showcase con más autonomía para el de 13 | E7: El de 13 ya disfruta la parte cultural de World Showcase.
A8: 4 | B8: Mar 23 mar | C8: Universal Studios + Islands of Adventure | D8: • Mañana: VelociCoaster (51"), Jurassic World, Hagrid's Magical Creatures Motorbike Adventure (48") • Mediodía: The Amazing Adventures of Spider-Man (40"), Hollywood Rip Ride Rockit (51") • Tarde: Harry Potter and the Forbidden Journey, Escape from Gringotts | E8: Si el de 9 no llega a 48-51", usar Child Swap / Single Rider.
A9: 5 | B9: Mié 24 mar | C9: Hollywood Studios | D9: • Mañana: Rise of the Resistance, Millennium Falcon: Smugglers Run • Mediodía: Tower of Terror, Rock 'n' Roller Coaster • Tarde: Toy Story Land, Star Tours • Noche: Fantasmic | E9: Galaxy's Edge es el sector estrella para el de 13.
A10: 6 | B10: Jue 25 mar | C10: Universal Epic Universe | D10: • Mañana: Stardust Racers (42", coaster insignia), Harry Potter and the Battle at the Ministry (40") • Mediodía: Monsters Unchained (48"), Curse of the Werewolf (40") • Tarde: Hiccup's Wing Gliders (40"), Mario Kart: Bowser's Challenge (40") • El de 9 puede necesitar Child Swap en Stardust Racers/Monsters Unchained (48"+) | E10: Stardust Racers y Battle at the Ministry son de lo más esperado del parque.
A11: 7 | B11: Vie 26 mar | C11: Animal Kingdom | D11: • Mañana: Avatar Flight of Passage (44"), Expedition Everest (44") • Mediodía: Kali River Rapids (38", se mojan), Kilimanjaro Safaris junto a la familia • Tarde: Na'vi River Journey, Dinosaur (40") | E11: Expedition Everest y Flight of Passage son de lo mejor del parque para esta edad.
A12: 8 | B12: Sáb 27 mar | C12: Día libre / compras / pileta | D12: Día libre en familia — pileta del resort, Disney Springs, descanso. Sin plan de parque.
B13: Dom 28 mar | C13: Check-out + vuelo a Bogotá | D13: Check-out, traslado al aeropuerto, vuelo de regreso a Bogotá.
A15: Fuentes: alturas mínimas según Disney/Universal (TouringPlans, MagicGuides, ThrillZing, NBC Insider, DeepArrival — consultadas sep-2026). Verificar altura real de cada niño antes del viaje.

Sheet Hotel — Opciones económicas
A1: HOTEL — COMPARACIÓN DE OPCIONES (2 habitaciones, 8 noches)
A2: La Opción 1 (Art of Animation) es la que ya está usada en 'Grupo A' y 'Grupo B'. Estas son alternativas más económicas para comparar — no reemplazan los números del resto de la planilla.
B4: Disney's Art of Animation | C4: DoubleTree Suites by Hilton — Disney Springs Area | D4: Holiday Inn Resort Orlando Suites — Waterpark
A5: Tipo de propiedad | B5: Resort oficial Disney (dentro del parque) | C5: Hotel 'Good Neighbor' oficial — a 1 milla de Disney Springs | D5: Hotel independiente 'Good Neighbor' — a 1 milla de Disney World
A6: Calificación | B6: No aplica (propiedad Disney) | C6: 8.2 / 10 — 'Muy bueno' (921 reseñas, Kayak/Hilton) | D6: 6.5-7.8 / 10 — 'Bueno' (5,405 reseñas, Hotels.com/Kayak)
A7: Estrellas | B7: Value (2 llaves Disney) | C7: 4 estrellas | D7: 3-3.5 estrellas
A8: Tipo de habitación | B8: Family Suite (duerme 6): 1 queen + sofá cama + cama abatible | C8: 1-Bedroom Suite (duerme hasta 4-5): king/2 queens + sofá cama | D8: 2-Bedroom Suite (duerme 6): 1 king + litera + sofá cama
A9: Transporte a parques Disney | B9: Incluido — bus/monorriel/barco gratis | C9: Incluido — shuttle gratis + early park access (hotel oficial Disney Springs) | D9: NO incluido — sin shuttle propio
A10: Transporte a Universal/Epic Universe | B10: No incluido (Uber, ~15-20 min) | C10: No incluido (Uber, ~15-20 min) | D10: No incluido (Uber, ~15-20 min)
A11: Extra: parque acuático propio | B11: No | C11: No | D11: Sí — Surf & Splash Waterpark incluido en la tarifa
A13: COSTOS (8 noches, 2 habitaciones — Grupo A + Grupo B)
A14: Concepto | B14: Opción 1 (USD) | C14: Opción 2 (USD) | D14: Opción 3 (USD)
A15: Tarifa estimada por noche (por habitación, pico Semana Santa) | B15: 808 | C15: 320 | D15: 320
A16: Cargo adicional (resort fee / adulto extra) por noche | B16: 15 | C16: 0 | D16: 45
A17: Noches | B17: 8 | C17: 8 | D17: 8
A18: Subtotal hotel — 2 habitaciones | B18: =(B15+15)*B17 + B15*B17 -> 13048 | C18: =(C15+C16)*C17*2 -> 5120 | D18: =(D15+D16)*D17*2 -> 5840
A20: TRANSPORTE ADICIONAL NECESARIO (Uber)
A21: Días de parque Disney (4 días) — Uber ida y vuelta x2 grupos | B21: 0 | C21: 0 | D21: =4*2*35 -> 280
A22: Días Universal + Epic Universe (2 días) — Uber ida y vuelta x2 grupos | B22: =2*2*35 -> 140 | C22: =2*2*35 -> 140 | D22: =2*2*35 -> 140
A23: Subtotal transporte adicional | B23: =B21+B22 -> 140 | C23: =C21+C22 -> 140 | D23: =D21+D22 -> 420
A25: TOTAL HOTEL + TRANSPORTE | B25: =B18+B23 -> 13188 | C25: =C18+C23 -> 5260 | D25: =D18+D23 -> 6260
A26: Ahorro vs. Opción 1 | C26: =B25-C25 -> 7928 | D26: =B25-D25 -> 6928
A28: Links de reserva
A29: Disney's Art of Animation — reservar | B29: DoubleTree Suites (Hilton) — reservar | C29: Holiday Inn Waterpark (IHG) — reservar
A31: Notas
A32: • DoubleTree Suites es un hotel oficial de Disney Springs Resort Area: aunque no es propiedad de Disney, da los mismos beneficios de transporte gratis a los 4 parques + early park access — por eso no necesita Uber extra para los días Disney.
A33: • Holiday Inn Waterpark es más barato pero NO tiene shuttle propio: hay que sumar Uber para TODOS los días de parque (Disney + Universal + Epic Universe), estimado en $35 ida y vuelta por grupo por día.
A34: • Tarifas de temporada pico (Semana Santa) ESTIMADAS a partir de tarifas base publicadas fuera de temporada alta (no hay calendario oficial de marzo 2027 para estos hoteles todavía) — multiplicador ~2-2.5x aplicado. Confirmar con los links antes de reservar.
A35: • Esta hoja es solo comparativa — el resto de la planilla ('Resumen', 'Grupo A', 'Grupo B') sigue usando la Opción 1 (Art of Animation). Avisame si querés que cambie los totales a la Opción 2 o 3.
